Workbook

Sheet lista usuarios
A1: No. USUARIO | B1: NOMBRE | C1: DIRECCION | D1: AÑO | E1: ENTREGADOS | F1: PAGADOS
A2: ='BASE DE DATOS'!B2 -> 1 | B2: =VLOOKUP(A2,'BASE DE DATOS'!$B$2:$AB$702,2,0) -> ABUNDIO CRESCENCIO LORENZO | C2: =VLOOKUP(A2,'BASE DE DATOS'!$B$2:$AB$6821,12,0) -> 15 PONIENTE ESQ, 7 SUR | D2: =VLOOKUP(A2,'BASE DE DATOS'!$B$2:$AB$6821,13,0) -> 2026
A3: ='BASE DE DATOS'!B3 -> 2 | B3: =VLOOKUP(A3,'BASE DE DATOS'!$B$2:$AB$702,2,0) -> ABUNDIO JIMENEZ LEOBARDO | C3: =VLOOKUP(A3,'BASE DE DATOS'!$B$2:$AB$6821,12,0) -> 7 SUR ENTRE 11 Y 13 PONIENTE | D3: =VLOOKUP(A3,'BASE DE DATOS'!$B$2:$AB$6821,13,0) -> 2023
A4: ='BASE DE DATOS'!B4 -> 3 | B4: =VLOOKUP(A4,'BASE DE DATOS'!$B$2:$AB$702,2,0) -> ABUNDIO JIMENEZ ROMARICO | C4: =VLOOKUP(A4,'BASE DE DATOS'!$B$2:$AB$6821,12,0) -> 7 SUR ENTRE 11 Y 13 PTE | D4: =VLOOKUP(A4,'BASE DE DATOS'!$B$2:$AB$6821,13,0) -> 2026
A5: ='BASE DE DATOS'!B5 -> 4 | B5: =VLOOKUP(A5,'BASE DE DATOS'!$B$2:$AB$702,2,0) -> ABUNDIO JUAREZ GABRIELA | C5: =VLOOKUP(A5,'BASE DE DATOS'!$B$2:$AB$6821,12,0) -> 7 SUR ENTRE 15 Y 17 PTE. | D5: =VLOOKUP(A5,'BASE DE DATOS'!$B$2:$AB$6821,13,0) -> 2026
A6: ='BASE DE DATOS'!B6 -> 5 | B6: =VLOOKUP(A6,'BASE DE DATOS'!$B$2:$AB$702,2,0) -> ABUNDIO JUAREZ JOSE LUIS | C6: =VLOOKUP(A6,'BASE DE DATOS'!$B$2:$AB$6821,12,0) -> 15 PTE. NO. 2006 | D6: =VLOOKUP(A6,'BASE DE DATOS'!$B$2:$AB$6821,13,0) -> 2026
A7: ='BASE DE DATOS'!B7 -> 6 | B7: =VLOOKUP(A7,'BASE DE DATOS'!$B$2:$AB$702,2,0) -> ABUNDIO JUAREZ ROSA MARIA | C7: =VLOOKUP(A7,'BASE DE DATOS'!$B$2:$AB$6821,12,0) -> 7 SUR ENTRE 15 Y 17 PONIENTE | D7: =VLOOKUP(A7,'BASE DE DATOS'!$B$2:$AB$6821,13,0) -> 0
A8: ='BASE DE DATOS'!B8 -> 7 | B8: =VLOOKUP(A8,'BASE DE DATOS'!$B$2:$AB$702,2,0) -> ABUNDIO JUAREZ VICTOR GUILLERMO | C8: =VLOOKUP(A8,'BASE DE DATOS'!$B$2:$AB$6821,12,0) -> 7 SUR ENTRE 11 Y 13 PTE. | D8: =VLOOKUP(A8,'BASE DE DATOS'!$B$2:$AB$6821,13,0) -> 2026
A9: ='BASE DE DATOS'!B9 -> 8 | B9: =VLOOKUP(A9,'BASE DE DATOS'!$B$2:$AB$702,2,0) -> ABUNDIO LOPEZ JESUS MAURO | C9: =VLOOKUP(A9,'BASE DE DATOS'!$B$2:$AB$6821,12,0) -> 7 SUR ENTRE 11 Y 13 PONIENTE | D9: =VLOOKUP(A9,'BASE DE DATOS'!$B$2:$AB$6821,13,0) -> 2023
A10: ='BASE DE DATOS'!B10 -> 9 | B10: =VLOOKUP(A10,'BASE DE DATOS'!$B$2:$AB$702,2,0) -> ABUNDIO RODRIGUEZ LUIS MANUEL | C10: =VLOOKUP(A10,'BASE DE DATOS'!$B$2:$AB$6821,12,0) -> 15 PTE. NO. 2006 ENT. 7 Y 9 SUR | D10: =VLOOKUP(A10,'BASE DE DATOS'!$B$2:$AB$6821,13,0) -> 0
A11: ='BASE DE DATOS'!B11 -> 10 | B11: =VLOOKUP(A11,'BASE DE DATOS'!$B$2:$AB$702,2,0) -> ADAN GONZALEZ LIDIA | C11: =VLOOKUP(A11,'BASE DE DATOS'!$B$2:$AB$6821,12,0) -> 9 SUR ENTRE 21 PTE. Y CANAL | D11: =VLOOKUP(A11,'BASE DE DATOS'!$B$2:$AB$6821,13,0) -> 2026
A12: ='BASE DE DATOS'!B12 -> 11 | B12: =VLOOKUP(A12,'BASE DE DATOS'!$B$2:$AB$702,2,0) -> AGUILAR GUERRERO JESUS | C12: =VLOOKUP(A12,'BASE DE DATOS'!$B$2:$AB$6821,12,0) -> 9 SUR ENTRE 21 PTE. Y CANAL | D12: =VLOOKUP(A12,'BASE DE DATOS'!$B$2:$AB$6821,13,0) -> 2026
A13: ='BASE DE DATOS'!B13 -> 12 | B13: =VLOOKUP(A13,'BASE DE DATOS'!$B$2:$AB$702,2,0) -> ALCANTARA ANGEL AMELIA | C13: =VLOOKUP(A13,'BASE DE DATOS'!$B$2:$AB$6821,12,0) -> 13 PONIENE 701 ENTRE 7 Y 9 SUR | D13: =VLOOKUP(A13,'BASE DE DATOS'!$B$2:$AB$6821,13,0) -> 2025
... A159: ='BASE DE DATOS'!B159 -> 154 | B159: =VLOOKUP(A159,'BASE DE DATOS'!$B$2:$AB$702,2,0) -> GONZALEZ MARTINEZ JOSE ODILON | C159: =VLOOKUP(A159,'BASE DE DATOS'!$B$2:$AB$6821,12,0) -> 21 PTE. ENTRE 13 Y 15 SUR | D159: =VLOOKUP(A159,'BASE DE DATOS'!$B$2:$AB$6821,13,0) -> 2026
A160: ='BASE DE DATOS'!B161 -> 155 | B160: =VLOOKUP(A160,'BASE DE DATOS'!$B$2:$AB$702,2,0) -> GONZALEZ RAMIREZ RAFAEL | C160: =VLOOKUP(A160,'BASE DE DATOS'!$B$2:$AB$6821,12,0) -> 13 PTE ENTRE 11 Y 13 SUR | D160: =VLOOKUP(A160,'BASE DE DATOS'!$B$2:$AB$6821,13,0) -> 2026
A161: ='BASE DE DATOS'!B162 -> 156 | B161: =VLOOKUP(A161,'BASE DE DATOS'!$B$2:$AB$702,2,0) -> GONZALEZ ROSAS JOSE OMAR | C161: =VLOOKUP(A161,'BASE DE DATOS'!$B$2:$AB$6821,12,0) -> 21 PTE. ENTRE 13 Y 15 SUR | D161: =VLOOKUP(A161,'BASE DE DATOS'!$B$2:$AB$6821,13,0) -> 2021
A162: ='BASE DE DATOS'!B163 -> 157 | B162: =VLOOKUP(A162,'BASE DE DATOS'!$B$2:$AB$702,2,0) -> SANTOS GONZALEZ SANDRA | C162: =VLOOKUP(A162,'BASE DE DATOS'!$B$2:$AB$6821,12,0) -> 15 PONIENTE NO 1906 | D162: =VLOOKUP(A162,'BASE DE DATOS'!$B$2:$AB$6821,13,0) -> 2026
A163: ='BASE DE DATOS'!B164 -> 158 | B163: =VLOOKUP(A163,'BASE DE DATOS'!$B$2:$AB$702,2,0) -> GUZMAN JUAREZ RIGOBERTO | C163: =VLOOKUP(A163,'BASE DE DATOS'!$B$2:$AB$6821,12,0) -> 17 SUR ENTRE 15 Y 17 PONIENTE | D163: =VLOOKUP(A163,'BASE DE DATOS'!$B$2:$AB$6821,13,0) -> 2026
A164: ='BASE DE DATOS'!B165 -> 159 | B164: =VLOOKUP(A164,'BASE DE DATOS'!$B$2:$AB$702,2,0) -> SANTOS VAZQUEZ MARIA GUADALUPE | C164: =VLOOKUP(A164,'BASE DE DATOS'!$B$2:$AB$6821,12,0) -> 15 PONIENTEE 902 ENTRE 9 Y 11 SUR | D164: =VLOOKUP(A164,'BASE DE DATOS'!$B$2:$AB$6821,13,0) -> 2026
A165: ='BASE DE DATOS'!B166 -> 160 | B165: =VLOOKUP(A165,'BASE DE DATOS'!$B$2:$AB$702,2,0) -> HERNANDEZ VAZQUEZ PEDRO | C165: =VLOOKUP(A165,'BASE DE DATOS'!$B$2:$AB$6821,12,0) -> 15 SUR ENT. 15 Y 17 PTE | D165: =VLOOKUP(A165,'BASE DE DATOS'!$B$2:$AB$6821,13,0) -> 2026
A166: ='BASE DE DATOS'!B167 -> 161 | B166: =VLOOKUP(A166,'BASE DE DATOS'!$B$2:$AB$702,2,0) -> HUERTA RODRIGUEZ CARMEN | C166: =VLOOKUP(A166,'BASE DE DATOS'!$B$2:$AB$6821,12,0) -> 17 PONIENTE ENTRE 13 Y 15 SUR | D166: =VLOOKUP(A166,'BASE DE DATOS'!$B$2:$AB$6821,13,0) -> 2026
A167: ='BASE DE DATOS'!B168 -> 162 | B167: =VLOOKUP(A167,'BASE DE DATOS'!$B$2:$AB$702,2,0) -> LOZANO MONTES RODE | C167: =VLOOKUP(A167,'BASE DE DATOS'!$B$2:$AB$6821,12,0) -> 13 SUR ENTRE 15 Y 17 PTE. | D167: =VLOOKUP(A167,'BASE DE DATOS'!$B$2:$AB$6821,13,0) -> 2026
A168: ='BASE DE DATOS'!B169 -> 163 | B168: =VLOOKUP(A168,'BASE DE DATOS'!$B$2:$AB$702,2,0) -> HUERTA RODRIGUEZ JAQUELINE | C168: =VLOOKUP(A168,'BASE DE DATOS'!$B$2:$AB$6821,12,0) -> 17 PTE. ENTRE 13 Y 15 SUR | D168: =VLOOKUP(A168,'BASE DE DATOS'!$B$2:$AB$6821,13,0) -> 2026
A169: ='BASE DE DATOS'!B170 -> 164 | B169: =VLOOKUP(A169,'BASE DE DATOS'!$B$2:$AB$702,2,0) -> SANTOS GONZALEZ SANDRA | C169: =VLOOKUP(A169,'BASE DE DATOS'!$B$2:$AB$6821,12,0) -> 15 PTE NO. 1906 | D169: =VLOOKUP(A169,'BASE DE DATOS'!$B$2:$AB$6821,13,0) -> 2018
A170: ='BASE DE DATOS'!B171 -> 165 | B170: =VLOOKUP(A170,'BASE DE DATOS'!$B$2:$AB$702,2,0) -> ISLAS RODRIGUEZ MARIA LUISA | C170: =VLOOKUP(A170,'BASE DE DATOS'!$B$2:$AB$6821,12,0) -> 11 SUR ENTRE 15 Y 17 PTE | D170: =VLOOKUP(A170,'BASE DE DATOS'!$B$2:$AB$6821,13,0) -> 2026
A171: ='BASE DE DATOS'!B172 -> 166 | B171: =VLOOKUP(A171,'BASE DE DATOS'!$B$2:$AB$702,2,0) -> ISLAS SANTOS FERNANDO | C171: =VLOOKUP(A171,'BASE DE DATOS'!$B$2:$AB$6821,12,0) -> 15 PTE. NO. 1705 | D171: =VLOOKUP(A171,'BASE DE DATOS'!$B$2:$AB$6821,13,0) -> 2026
... A228: ='BASE DE DATOS'!B229 -> 220 | B228: =VLOOKUP(A228,'BASE DE DATOS'!$B$2:$AB$702,2,0) -> LOPEZ SANCHEZ ANTONIO | C228: =VLOOKUP(A228,'BASE DE DATOS'!$B$2:$AB$6821,12,0) -> 13 SUR ENTRE 21 Y LATERAL | D228: =VLOOKUP(A228,'BASE DE DATOS'!$B$2:$AB$6821,13,0) -> 2025
A229: ='BASE DE DATOS'!B231 -> 221 | B229: =VLOOKUP(A229,'BASE DE DATOS'!$B$2:$AB$702,2,0) -> LOPEZ SANTOS ARACELI | C229: =VLOOKUP(A229,'BASE DE DATOS'!$B$2:$AB$6821,12,0) -> 13 PONIENTE Y PRIV. DE LA 7 SUR | D229: =VLOOKUP(A229,'BASE DE DATOS'!$B$2:$AB$6821,13,0) -> 0
A230: ='BASE DE DATOS'!B232 -> 222 | B230: =VLOOKUP(A230,'BASE DE DATOS'!$B$2:$AB$702,2,0) -> LOPEZ SANCHEZ ENRIQUE | C230: =VLOOKUP(A230,'BASE DE DATOS'!$B$2:$AB$6821,12,0) -> 21 PTE ESQ. 13 SUR | D230: =VLOOKUP(A230,'BASE DE DATOS'!$B$2:$AB$6821,13,0) -> 2026
A231: ='BASE DE DATOS'!B233 -> 223 | B231: =VLOOKUP(A231,'BASE DE DATOS'!$B$2:$AB$702,2,0) -> LOPEZ SANCHEZ FIDEL | C231: =VLOOKUP(A231,'BASE DE DATOS'!$B$2:$AB$6821,12,0) -> 21 PTE. ENTRE 13 SUR Y CANAL | D231: =VLOOKUP(A231,'BASE DE DATOS'!$B$2:$AB$6821,13,0) -> 2025
A232: ='BASE DE DATOS'!B234 -> 224 | B232: =VLOOKUP(A232,'BASE DE DATOS'!$B$2:$AB$702,2,0) -> LOPEZ SANCHEZ MARIA SOLEDAD | C232: =VLOOKUP(A232,'BASE DE DATOS'!$B$2:$AB$6821,12,0) -> 13 SUR 21 PTE Y CANAL | D232: =VLOOKUP(A232,'BASE DE DATOS'!$B$2:$AB$6821,13,0) -> 2020
A233: ='BASE DE DATOS'!B235 -> 225 | B233: =VLOOKUP(A233,'BASE DE DATOS'!$B$2:$AB$702,2,0) -> LOPEZ SANCHEZ MARIA AMALIA | C233: =VLOOKUP(A233,'BASE DE DATOS'!$B$2:$AB$6821,12,0) -> 15 PTE ENTRE 7 Y 9 SUR | D233: =VLOOKUP(A233,'BASE DE DATOS'!$B$2:$AB$6821,13,0) -> 2026
A234: ='BASE DE DATOS'!B236 -> 226 | B234: =VLOOKUP(A234,'BASE DE DATOS'!$B$2:$AB$702,2,0) -> LOPEZ SANCHEZ MARIA CANDELARIA | C234: =VLOOKUP(A234,'BASE DE DATOS'!$B$2:$AB$6821,12,0) -> 13 SUR ENTRE 21 PTE Y CANAL | D234: =VLOOKUP(A234,'BASE DE DATOS'!$B$2:$AB$6821,13,0) -> 2025
A235: ='BASE DE DATOS'!B237 -> 227 | B235: =VLOOKUP(A235,'BASE DE DATOS'!$B$2:$AB$702,2,0) -> LOPEZ SANCHEZ MARIA DE LOURDES | C235: =VLOOKUP(A235,'BASE DE DATOS'!$B$2:$AB$6821,12,0) -> 21 PONIENTE ENTRE 13 Y 15 SUR | D235: =VLOOKUP(A235,'BASE DE DATOS'!$B$2:$AB$6821,13,0) -> 2026
A236: ='BASE DE DATOS'!B238 -> 228 | B236: =VLOOKUP(A236,'BASE DE DATOS'!$B$2:$AB$702,2,0) -> MONTIEL JIMENEZ MARCO ANTONIO | C236: =VLOOKUP(A236,'BASE DE DATOS'!$B$2:$AB$6821,12,0) -> 15 PTE 15 SUR | D236: =VLOOKUP(A236,'BASE DE DATOS'!$B$2:$AB$6821,13,0) -> 2026
A237: ='BASE DE DATOS'!B239 -> 229 | B237: =VLOOKUP(A237,'BASE DE DATOS'!$B$2:$AB$702,2,0) -> LOPEZ SANCHEZ MARTIN | C237: =VLOOKUP(A237,'BASE DE DATOS'!$B$2:$AB$6821,12,0) -> 13 SUR ENTRE 21 PTE Y CANAL | D237: =VLOOKUP(A237,'BASE DE DATOS'!$B$2:$AB$6821,13,0) -> 2026
A238: ='BASE DE DATOS'!B240 -> 230 | B238: =VLOOKUP(A238,'BASE DE DATOS'!$B$2:$AB$702,2,0) -> LOPEZ SANCHEZ RUFINO | C238: =VLOOKUP(A238,'BASE DE DATOS'!$B$2:$AB$6821,12,0) -> 15 PTE. ENTRE 7 Y 9 SUR | D238: =VLOOKUP(A238,'BASE DE DATOS'!$B$2:$AB$6821,13,0) -> 2026
A239: ='BASE DE DATOS'!B241 -> 231 | B239: =VLOOKUP(A239,'BASE DE DATOS'!$B$2:$AB$702,2,0) -> LOPEZ SANCHEZ SERGIO | C239: =VLOOKUP(A239,'BASE DE DATOS'!$B$2:$AB$6821,12,0) -> 15 PONIENTE ENTRE PRIV 7 SURY 9 SUR | D239: =VLOOKUP(A239,'BASE DE DATOS'!$B$2:$AB$6821,13,0) -> 2026
A240: ='BASE DE DATOS'!B242 -> 232 | B240: =VLOOKUP(A240,'BASE DE DATOS'!$B$2:$AB$702,2,0) -> LOPEZ SANTOS JAVIER | C240: =VLOOKUP(A240,'BASE DE DATOS'!$B$2:$AB$6821,12,0) -> 13 PTE. NO. 908 | D240: =VLOOKUP(A240,'BASE DE DATOS'!$B$2:$AB$6821,13,0) -> 2026
... A246: ='BASE DE DATOS'!B248 -> 237 | B246: =VLOOKUP(A246,'BASE DE DATOS'!$B$2:$AB$702,2,0) -> LOPEZ ZAMORA DELFINO | C246: =VLOOKUP(A246,'BASE DE DATOS'!$B$2:$AB$6821,12,0) -> 15 PTE. ENTRE 7 Y 9 SUR | D246: =VLOOKUP(A246,'BASE DE DATOS'!$B$2:$AB$6821,13,0) -> 2026
...

Sheet BASE DE DATOS
A1: OBSERVACIONES ANTERIOR COMITÉ | B1: No. USUARIO | C1: NOMBRE | D1: SECCIONAR | E1: T. POZO | F1: TOMA | G1: CONAGUA | H1: DRENAJE | I1: HIDRANTE | J1: INQUILINO | K1: VACAS | L1: OBSERVACIONES | M1: DIRECCION | N1: AÑO | O1: ENERO | P1: FEBRERO | Q1: MARZO | R1: ABRIL | S1: MAYO | T1: JUNIO | U1: JULIO | V1: AGOSTO | W1: SEPTIEMBRE | X1: OCTUBRE | Y1: NOVIEMBRE | Z1: DICIEMBRE | AA1: OBSERVACIONES ANTERIOR COMITÉ | AB1: 2019
B2: 1 | C2: ABUNDIO CRESCENCIO LORENZO | D2: 300 | E2: 150 | F2: 1 | G2: 320 | M2: 15 PONIENTE ESQ, 7 SUR | N2: 2026
B3: 2 | C3: ABUNDIO JIMENEZ LEOBARDO | D3: 300 | E3: 150 | F3: 1 | G3: 320 | M3: 7 SUR ENTRE 11 Y 13 PONIENTE | N3: 2023 | O3: PAGADO | P3: PAGADO | Q3: PAGADO | R3: PAGADO | S3: PAGADO | AB3: PENDIENTE INASISTENCIAS
B4: 3 | C4: ABUNDIO JIMENEZ ROMARICO | D4: 300 | E4: 150 | F4: 1 | G4: 320 | M4: 7 SUR ENTRE 11 Y 13 PTE | N4: 2026
B5: 4 | C5: ABUNDIO JUAREZ GABRIELA | D5: 300 | E5: 150 | F5: 1 | G5: 320 | M5: 7 SUR ENTRE 15 Y 17 PTE. | N5: 2026
B6: 5 | C6: ABUNDIO JUAREZ JOSE LUIS | D6: 300 | E6: 150 | F6: 1 | G6: 320 | M6: 15 PTE. NO. 2006 | N6: 2026
A7: CANCELADA | B7: 6 | C7: ABUNDIO JUAREZ ROSA MARIA | F7: 1 | G7: CORTADA | M7: 7 SUR ENTRE 15 Y 17 PONIENTE | N7: 0 | O7: CORTADA | AA7: CANCELADA
B8: 7 | C8: ABUNDIO JUAREZ VICTOR GUILLERMO | D8: 300 | E8: 150 | F8: 1 | G8: 320 | M8: 7 SUR ENTRE 11 Y 13 PTE. | N8: 2026
B9: 8 | C9: ABUNDIO LOPEZ JESUS MAURO | D9: 600 | E9: 300 | F9: 2 | G9: 320 | M9: 7 SUR ENTRE 11 Y 13 PONIENTE | N9: 2023 | O9: PAGADO 2 | P9: PAGADO 2 | Q9: PAGADO 2 | R9: PAGADO 2 | S9: PAGADO 2 | AB9: PENDIENTE INASISTENCIAS, TIENE DOS TOMAS Y SIGUE ATRASADO
A10: CAMBIO DE DOMICILIO | B10: 9 | C10: ABUNDIO RODRIGUEZ LUIS MANUEL | F10: 1 | M10: 15 PTE. NO. 2006 ENT. 7 Y 9 SUR | N10: 0 | S10: PAGADO | T10: PAGADO | U10: PAGADO | V10: PAGADO | AA10: CAMBIO DE DOMICILIO
B11: 10 | C11: ADAN GONZALEZ LIDIA | D11: 300 | E11: 150 | F11: 1 | G11: 320 | H11: NO | M11: 9 SUR ENTRE 21 PTE. Y CANAL | N11: 2026
B12: 11 | C12: AGUILAR GUERRERO JESUS | D12: 300 | E12: 150 | F12: 1 | G12: 320 | H12: NO | M12: 9 SUR ENTRE 21 PTE. Y CANAL | N12: 2026
B13: 12 | C13: ALCANTARA ANGEL AMELIA | D13: 600 | E13: 300 | F13: 2 | G13: 320 | M13: 13 PONIENE 701 ENTRE 7 Y 9 SUR | N13: 2025 | O13: PAGADO | P13: PAGADO | Q13: PAGADO | R13: PAGADO | S13: PAGADO | T13: PAGADO | U13: PAGADO | V13: PAGADO | AB13: TOMA NUEVA EN OCT 2017
B14: 13 | C14: ALEJO CASTILLO MERCED | E14: 150 | F14: 1 | G14: 320 | M14: 17 PONIENTE ENTRE 15 Y 17 SUR | N14: 2026
A15: CANCELADA | B15: 14 | C15: ALONSO MONTIEL ARIADNA | F15: 1 | M15: 17 SUR ENTRE 15 Y 17 PTE. | N15: 0 | AA15: CANCELADA
B16: 15 | C16: ALONSO MONTIEL JORGE | D16: 300 | E16: 150 | F16: 1 | M16: 17 SUR ENTRE 15 Y 17 PTE. | N16: 2026
B17: 16 | C17: ANDRADE JIMENEZ JUAN MARINO | D17: 300 | E17: 150 | F17: 1 | G17: 320 | M17: 11 SUR ENTRE 15 Y 17 PTE. | N17: 2024
B18: 17 | C18: ANDRADE LOPEZ LUIS | D18: 300 | E18: 150 | F18: 1 | G18: 320 | M18: 13 SUR ENTRE 21 | N18: 2026
B19: 18 | C19: ANDRADE MENDEZ JUAN | D19: 300 | E19: 150 | F19: 1 | G19: 320 | J19: 2 | M19: 7 PTE. NO. 1503 | N19: 2026
B20: 19 | C20: ANDRADE VAZQUEZ FERNANDO | D20: 600 | E20: 300 | F20: 2 | G20: 640 | H20: NO | J20: 1 | M20: 21 PTE. ENTRE 7 Y 9 SUR | N20: 2026 | AB20: 3 TOMAS
B21: 20 | C21: APOLINAR VELAZQUEZ JESUS ANTONIO | D21: 300 | E21: 150 | F21: 1 | G21: 320 | M21: 15 PONIENTEE 710 7 Y 9 SUR | N21: 2025
B22: 21 | C22: ARENAS GONZALEZ JAQUELINE | D22: 300 | E22: 150 | F22: 1 | G22: 320 | H22: NO | M22: 19 PTE. ENTRE 11 Y 13 SUR | N22: 2026
B23: 22 | C23: ARENAS GONZALEZ RODOLFO | D23: 300 | E23: 150 | F23: 1 | G23: 320 | H23: NO | M23: 19 PTE. ESQ. 11 SUR | N23: 2026 | AB23: PAGO 12 INASISTENCIAS
B24: 23 | C24: GONZALEZ ZUÑIGA MARIA ENRIQUETA | D24: 300 | E24: 150 | F24: 1 | G24: 320 | M24: 11 SUR ENTRE 13 Y 15 PTE. | N24: 2026
B25: 24 | C25: AVELINO MONTIEL FERNANDO | D25: 300 | E25: 150 | F25: 1 | G25: 320 | H25: NO | M25: 9 SUR ENTRE 19 Y 21 PTE. | N25: 2026
B26: 25 | C26: AVELINO ALEJO DANIEL | D26: 300 | E26: 150 | F26: 1 | G26: 320 | M26: 13 PONIENTE Y 15 SUR | N26: 2026
B27: 26 | C27: AVELINO ALEJO MIGUEL | D27: 300 | E27: 150 | F27: 1 | G27: 320 | M27: 15 SUR 1107 | N27: 2026
B28: 27 | C28: AVELINO ANDRADE RUTH | D28: 300 | E28: 150 | F28: 1 | G28: 320 | M28: 7 SUR ESQ, 17 PTE. | N28: 2026 | AB28: PAGO 3 INASISTENCIAS
B29: 28 | C29: AVELINO HERNANDEZ GABRIEL | D29: 300 | E29: 150 | F29: 1 | G29: 320 | H29: NO | M29: 21 PTE. ENTRE 7 Y 9 SUR5 | N29: 2026
B30: 29 | C30: AVELINO MONTIEL EMILIA | D30: 300 | E30: 150 | F30: 1 | G30: 320 | H30: NO | M30: 13 SUR ENTRE CANAL Y BARRANCA | N30: 2026
B31: 30 | C31: AVELINO MONTIEL GUADALUPE | D31: 300 | E31: 150 | F31: 1 | G31: 320 | H31: NO | M31: 9 SUR ENTRE 19 Y 21 PTE | N31: 2024
B32: 31 | C32: AVELINO MONTIEL LUCIA | D32: 300 | E32: 150 | F32: 1 | G32: 640 | H32: y si la paga | M32: 13 SUR 1105 Y 9 SUR | N32: 2026 | AB32: PAGA 1 TOM FALTA 1 DE 35 PAGO UN INQUILINO DE EN ERO A DIC. DE 2020.
B33: 31A | C33: AVELINO MONTIEL LUCIA | D33: 300 | F33: 1 | M33: 9 SUR # 2105 | N33: 2026
B34: 32 | C34: AVELINO MONTIEL MARCELA | D34: 300 | E34: 150 | F34: 1 | G34: 320 | L34: PAGA DOS INQUILINOS HASTA MAYO 2025 | M34: 13 SUR NO. 1102 ENTRE 11 Y 13 PON | N34: 2026 | AB34: PAGO DE 3 INQUILINOS DE JUNIO A OCT. 2019
B35: 33 | C35: AVELINO NOTARIO EFRAIN | D35: 300 | E35: 150 | F35: 1 | G35: 320 | H35: NO | M35: 11 SUR ENTRE 21 Y 23 PTE. | N35: 2026
B36: 34 | C36: AVELINO NOTARIO GILBERTO | D36: 300 | E36: 150 | F36: 1 | G36: 320 | H36: NO | M36: 23 PTE. ENTRE 9 Y 11 SUR | N36: 2026
B37: 35 | C37: AVELINO NOTARIO LILIA | D37: 300 | E37: 150 | F37: 1 | G37: 320 | H37: NO | M37: 21 PTE. ENTRE 7 Y 9 SUR | N37: 2026 | AB37: PAGO 2 NASISTENCIAS
B38: 36 | C38: AVELINO NOTARIO MARIELA | D38: 300 | E38: 150 | F38: 1 | G38: 320 | M38: 11 SUR No.-2109 ENTRE LATERAL Y BARRANCA | N38: 2026
B39: 37 | C39: AVELINO NOTARIO MONICA | D39: 300 | E39: 150 | F39: 1 | G39: 320 | H39: NO | M39: 21 PTE. ENTRE 7 Y 9 SUR | N39: 2026
A40: CANCELADA | B40: 38 | C40: AVELINO OJEDA ABRAHAM | F40: 1 | M40: 9 SUR ENTRE 21 PTE | N40: 0 | O40: CANCELADA | AA40: CANCELADA
...

Sheet RECIBO NUEVO
E1: COMITÉ DE AGUA POTABLE Y ALCANTARILLADO
E2: DEL BARRIO DE SAN ANTONIO TECAMACHALCO, PUE.
L3: NOTA: FOLIO SE FORMA CON NUMERO DE USUARIO Y AÑO ACTUAL
H5: FECHA : | I5: =TODAY() -> 45918 | L5: =VLOOKUP($C$7,'BASE DE DATOS'!$B$2:$AB$685,2,0) -> MONTIEL ROMAN FELIPE
A7: USUARIO No. | C7: 265 | J7: FOLIO: | K7: =CONCATENATE(24,C7) -> 24265 | L7: COOPERACIONES | O7: OBSERVACIONES
A9: NOMBRE: | C9: =VLOOKUP($C$7,'BASE DE DATOS'!$B$2:$AB$702,2,0) -> MONTIEL ROMAN FELIPE | H9: =VLOOKUP($C$7,'BASE DE DATOS'!$B$2:$AB$6821,12,0) -> 15 SUR ENTRE 19 Y 21 PTE. | L9: =VLOOKUP($C$7,'BASE DE DATOS'!$B$2:$AB$702,3,0) -> 300 | M9: =VLOOKUP($C$7,'BASE DE DATOS'!$B$2:$AB$702,4,0) -> 150 | O9: =VLOOKUP($C$7,'BASE DE DATOS'!$B$2:$AB$702,11,0) -> 0
A11: TOMAS: | B11: =VLOOKUP($C$7,'BASE DE DATOS'!$B$2:$AB$702,5,0) -> 1 | C11: =IF(B11=0,"HIDRANTE","USUARIO") -> USUARIO | L11: TOMAS: | M11: =VLOOKUP($C$7,'BASE DE DATOS'!$B$2:$AB$702,5,0) -> 1 | N11: =IF(M11=0,"HIDRANTE","USUARIO") -> USUARIO
A12: CONCEPTO | D12: CUOTA X TOMA | E12: FORMA DE PAGO | F12: VACAS | G12: INQUILINOS | H12: INASISTENCIA | I12: COOPERACIONES | J12: TOMA NUEVA | K12: TOTAL A PAGAR | L12: ADEUDO | M12: =VLOOKUP($C$7,'BASE DE DATOS'!$B$2:$AB$702,13,0) -> 2026
E13: =IF(E14>=12,"Anual","Mensual") -> Anual | L13: ENERO | M13: =VLOOKUP($C$7,'BASE DE DATOS'!$B$2:$AB$702,14,0) -> 0 | O13: INQUILINO
D14: 60 | E14: 12 | F14: =VLOOKUP($C$7,'BASE DE DATOS'!$B$2:$M$702,10,0) -> 0 | G14: =VLOOKUP($C$7,'BASE DE DATOS'!$B$2:$M$702,9,0) -> 0 | L14: FEBRERO | M14: =VLOOKUP($C$7,'BASE DE DATOS'!$B$2:$AB$702,15,0) -> 0 | O14: =VLOOKUP($C$7,'BASE DE DATOS'!$B$2:$AB$702,9,0) -> 0
A15: PAGO POR BOMBEO Y DISTRIBUCION | E15: =IF(B11=0,D14*E14,IF(B11>=1,D14*E14*B11,0)) -> 720 | F15: =((F14*13)*E14) -> 0 | G15: =(G14*E14)*70 -> 0 | H15: =H14*200 -> 0 | K15: =SUM(E15:J15) -> 720 | L15: MARZO | M15: =VLOOKUP($C$7,'BASE DE DATOS'!$B$2:$AB$702,16,0) -> 0
A16: DE AGUA POTABLE | I16: =IF($L$9=0,300,0) -> 0 | K16: =SUM(E16:J16) -> 0 | L16: ABRI | M16: =VLOOKUP($C$7,'BASE DE DATOS'!$B$2:$AB$702,17,0) -> 0
A17: De: | B17: ENERO A DICIEMBRE DE 2024 | I17: =IF($M$9=0,150,0) -> 0 | K17: =SUM(E17:J17) -> 0 | L17: MAYO | M17: =VLOOKUP($C$7,'BASE DE DATOS'!$B$2:$AB$702,18,0) -> 0
L18: JUNIO | M18: =VLOOKUP($C$7,'BASE DE DATOS'!$B$2:$AB$702,19,0) -> 0
J19: TOTAL | K19: =SUM(K15:K18) -> 720 | L19: JULIO | M19: =VLOOKUP($C$7,'BASE DE DATOS'!$B$2:$AB$702,20,0) -> 0
L20: AGOTO | M20: =VLOOKUP($C$7,'BASE DE DATOS'!$B$2:$AB$702,21,0) -> 0
L21: SEPTIEMBRE | M21: =VLOOKUP($C$7,'BASE DE DATOS'!$B$2:$AB$702,22,0) -> 0
L22: OCTUBRE | M22: =VLOOKUP($C$7,'BASE DE DATOS'!$B$2:$AB$702,23,0) -> 0
L23: NOVIEMBRE | M23: =VLOOKUP($C$7,'BASE DE DATOS'!$B$2:$AB$702,24,0) -> 0
L24: DICIEMBRE | M24: =VLOOKUP($C$7,'BASE DE DATOS'!$B$2:$AB$702,25,0) -> 0
C25: CARLOS LOPEZ SANTOS | I25: SELLO
A26: NOTA: 1.- ES NECESARIO CONSERVAR ESTE COMPROBANTE, DEBERA PRESENTARLO EN SU PROXIMO PAGO PARA CUALQUIER ACLARACIÓN.
A27: 2.- EL PAGO DE ESTE RECIBO NO TE LIBERA DE DEUDAS ANTERIORES. | K27: USUARIO
E30: COMITÉ DE AGUA POTABLE Y ALCANTARILLADO
E31: DEL BARRIO DE SAN ANTONIO TECAMACHALCO, PUE.
H34: FECHA: | I34: =TODAY() -> 45918
A36: USUARIO No. | C36: =C7 -> 265 | J36: =J7 -> FOLIO: | K36: =K7 -> 24265
A38: NOMBRE: | C38: =VLOOKUP($C$7,'BASE DE DATOS'!$B$2:$C$702,2,0) -> MONTIEL ROMAN FELIPE | H38: =VLOOKUP(C36,'BASE DE DATOS'!$B$2:$M$701,12,0) -> 15 SUR ENTRE 19 Y 21 PTE.
A40: TOMAS: | B40: =B11 -> 1 | C40: =C11 -> USUARIO
A41: =A12 -> CONCEPTO | D41: =D12 -> CUOTA X TOMA | E41: =E12 -> FORMA DE PAGO | F41: =F12 -> VACAS | G41: =G12 -> INQUILINOS | H41: =H12 -> INASISTENCIA | I41: =I12 -> COOPERACIONES | J41: =J12 -> TOMA NUEVA | K41: =K12 -> TOTAL A PAGAR
E42: =E13 -> Anual
D43: =D14 -> 60 | E43: =E14 -> 12 | F43: =F14 -> 0 | G43: =G14 -> 0 | H43: =H14 -> 0
A44: =A15 -> PAGO POR BOMBEO Y DISTRIBUCION | E44: =E15 -> 720 | F44: =F15 -> 0 | G44: =G15 -> 0 | H44: =H15 -> 0 | J44: =J15 -> 0 | K44: =K15 -> 720
A45: =A16 -> DE AGUA POTABLE | I45: =I16 -> 0 | K45: =K16 -> 0
A46: =A17 -> De: | B46: =B17 -> ENERO A DICIEMBRE DE 2024 | I46: =I17 -> 0 | K46: =K17 -> 0
J48: =J19 -> TOTAL | K48: =K19 -> 720
C54: =C25 -> CARLOS LOPEZ SANTOS | I54: =I25 -> SELLO
A55: =A26 -> NOTA: 1.- ES NECESARIO CONSERVAR ESTE COMPROBANTE, DEBERA PRESENTARLO EN SU PROXIMO PAGO PARA CUALQUIER ACLARACIÓN.
A56: =A27 -> 2.- EL PAGO DE ESTE RECIBO NO TE LIBERA DE DEUDAS ANTERIORES. | K56: COMITÉ

Sheet RECIBO CON RECARGOS
K2: FOLIO: | L2: =CONCATENATE(25,$C$7) -> 25538
F3: COMITÉ DE AGUA POTABLE Y ALCANTARILLADO | M3: NOTA: FOLIO SE FORMA CON NUMERO DE USUARIO Y AÑO ACTUAL
F4: DEL BARRIO DE SAN ANTONIO TECAMACHALCO, PUE.
M5: =VLOOKUP($C$7,'BASE DE DATOS'!$B$2:$AB$685,2,0) -> VALERIANO MARTINEZ MARIA DEL SOCORRO
I6: FECHA : | J6: =TODAY() -> 45918
A7: USUARIO No. | C7: 538 | M7: COOPERACIONES | P7: OBSERVACIONES
A9: NOMBRE: | C9: =VLOOKUP($C$7,'BASE DE DATOS'!$B$2:$AB$702,2,0) -> VALERIANO MARTINEZ MARIA DEL SOCORRO | I9: =VLOOKUP($C$7,'BASE DE DATOS'!$B$2:$AB$6821,12,0) -> 19 PTE. ENTRE 15 Y 17 SUR | M9: =VLOOKUP($C$7,'BASE DE DATOS'!$B$2:$AB$702,3,0) -> 300 | N9: =VLOOKUP($C$7,'BASE DE DATOS'!$B$2:$AB$702,4,0) -> 150 | P9: =VLOOKUP($C$7,'BASE DE DATOS'!$B$2:$AB$702,11,0) -> 0
A11: TOMAS: | B11: =VLOOKUP($C$7,'BASE DE DATOS'!$B$2:$AB$702,5,0) -> 1 | C11: =IF(B11=0,"HIDRANTE","USUARIO") -> USUARIO | M11: TOMAS: | N11: =VLOOKUP($C$7,'BASE DE DATOS'!$B$2:$AB$702,5,0) -> 1 | O11: =IF(N11=0,"HIDRANTE","USUARIO") -> USUARIO
A12: CONCEPTO | D12: FORMA DE PAGO | F12: =IF(F13>=12,"Anual","Mensual") -> Mensual | G12: VACAS | H12: INQUILINOS | I12: INASISTENCIA | J12: COOPERACIONES | K12: TOMA NUEVA | L12: TOTAL A PAGAR | M12: ADEUDO | N12: =VLOOKUP($C$7,'BASE DE DATOS'!$B$2:$AB$702,13,0) -> 2026
D13: CUOTA X TOMA | E13: 70 | M13: ENERO | N13: =VLOOKUP($C$7,'BASE DE DATOS'!$B$2:$AB$702,14,0) -> 0 | P13: INQUILINO
D14: CUOTA CON RECARGO | E14: 100 | F14: 10 | G14: =VLOOKUP($C$7,'BASE DE DATOS'!$B$2:$M$702,10,0) -> 0 | H14: =VLOOKUP($C$7,'BASE DE DATOS'!$B$2:$M$702,9,0) -> 0 | M14: FEBRERO | N14: =VLOOKUP($C$7,'BASE DE DATOS'!$B$2:$AB$702,15,0) -> 0 | P14: =VLOOKUP($C$7,'BASE DE DATOS'!$B$2:$AB$702,9,0) -> 0
A15: PAGO POR BOMBEO Y DISTRIBUCION | F15: =IF($B$11=0,$E$13*$F$13,IF($B$11>=1,$E$13*$F$13*$B$11,0)) -> 0 | G15: =($G$14*13)*$F$13 -> 0 | H15: =($H$14*$F$13)*70 -> 0 | I15: =I14*200 -> 0 | L15: =SUM(F15:K15) -> 0 | M15: MARZO | N15: =VLOOKUP($C$7,'BASE DE DATOS'!$B$2:$AB$702,16,0) -> 0
A16: DE AGUA POTABLE | F16: =IF($B$11=0,$E$14*$F$14,IF($B$11>=1,$E$14*$F$14*$B$11,0)) -> 1000 | G16: =($G$14*13)*$F$14 -> 0 | H16: =($H$14*$F$14)*100 -> 0 | L16: =SUM(F16:K16) -> 1000 | M16: ABRI | N16: =VLOOKUP($C$7,'BASE DE DATOS'!$B$2:$AB$702,17,0) -> 0
A17: De: | B17: MARZO A DICIEMBRE DE 2025 | J17: =IF($M$9=0,300,0) -> 0 | L17: =SUM(J17:K17) -> 0 | M17: MAYO | N17: =VLOOKUP($C$7,'BASE DE DATOS'!$B$2:$AB$702,18,0) -> 0
J18: =IF($N$9=0,150,0) -> 0 | L18: =SUM(J18:K18) -> 0 | M18: JUNIO | N18: =VLOOKUP($C$7,'BASE DE DATOS'!$B$2:$AB$702,19,0) -> 0
M19: JULIO | N19: =VLOOKUP($C$7,'BASE DE DATOS'!$B$2:$AB$702,20,0) -> 0
K20: TOTAL | L20: =SUM(L15:L19) -> 1000 | M20: AGOTO | N20: =VLOOKUP($C$7,'BASE DE DATOS'!$B$2:$AB$702,21,0) -> 0
M21: SEPTIEMBRE | N21: =VLOOKUP($C$7,'BASE DE DATOS'!$B$2:$AB$702,22,0) -> 0
M22: OCTUBRE | N22: =VLOOKUP($C$7,'BASE DE DATOS'!$B$2:$AB$702,23,0) -> 0
M23: NOVIEMBRE | N23: =VLOOKUP($C$7,'BASE DE DATOS'!$B$2:$AB$702,24,0) -> 0
M24: DICIEMBRE | N24: =VLOOKUP($C$7,'BASE DE DATOS'!$B$2:$AB$702,25,0) -> 0
C26: CARLOS LOPEZ SANTOS | J26: SELLO
A27: NOTA: 1.- ES NECESARIO CONSERVAR ESTE COMPROBANTE, DEBERA PRESENTARLO EN SU PROXIMO PAGO PARA CUALQUIER ACLARACIÓN.
A28: 2.- EL PAGO DE ESTE RECIBO NO TE LIBERA DE DEUDAS ANTERIORES. | L28: USUARIO
K32: =K2 -> FOLIO: | L32: =L2 -> 25538
F34: COMITÉ DE AGUA POTABLE Y ALCANTARILLADO
F35: DEL BARRIO DE SAN ANTONIO TECAMACHALCO, PUE.
I37: FECHA: | J37: =TODAY() -> 45918
A38: USUARIO No. | C38: =C7 -> 538
A40: NOMBRE: | C40: =VLOOKUP($C$7,'BASE DE DATOS'!$B$2:$C$702,2,0) -> VALERIANO MARTINEZ MARIA DEL SOCORRO | I40: =VLOOKUP(C38,'BASE DE DATOS'!$B$2:$M$701,12,0) -> 19 PTE. ENTRE 15 Y 17 SUR
A42: TOMAS: | B42: =B11 -> 1 | C42: =C11 -> USUARIO
A43: =A12 -> CONCEPTO | D43: FORMA DE PAGO | F43: =F12 -> Mensual | G43: =G12 -> VACAS | H43: =H12 -> INQUILINOS | I43: =I12 -> INASISTENCIA | J43: =J12 -> COOPERACIONES | K43: =K12 -> TOMA NUEVA | L43: =L12 -> TOTAL A PAGAR
D44: CUOTA X TOMA | E44: 70 | F44: =F13 -> 0
D45: CUOTA CON RECARGO | E45: 100 | F45: =F14 -> 10 | G45: =G14 -> 0 | H45: =H14 -> 0 | I45: =I14 -> 0
A46: =A15 -> PAGO POR BOMBEO Y DISTRIBUCION | F46: =F15 -> 0 | G46: =G15 -> 0 | H46: =H15 -> 0 | I46: =I15 -> 0 | K46: =K15 -> 0 | L46: =L15 -> 0
A47: =A16 -> DE AGUA POTABLE | F47: =F16 -> 1000 | G47: =G16 -> 0 | H47: =H16 -> 0 | L47: =L16 -> 1000
A48: =A17 -> De: | B48: =B17 -> MARZO A DICIEMBRE DE 2025 | J48: =J16 -> 0 | L48: =L17 -> 0
B49: =B18 -> 0 | J49: =J18 -> 0 | L49: =L18 -> 0
K51: =K20 -> TOTAL | L51: =L20 -> 1000
C57: =C26 -> CARLOS LOPEZ SANTOS | J57: =J26 -> SELLO
...

Sheet RECIBO 2025
K2: FOLIO: | L2: =CONCATENATE(25,$C$7) -> 25265
E3: COMITÉ DE AGUA POTABLE Y ALCANTARILLADO | M3: NOTA: FOLIO SE FORMA CON NUMERO DE USUARIO Y AÑO ACTUAL
E4: DEL BARRIO DE SAN ANTONIO TECAMACHALCO, PUE.
M5: =VLOOKUP($C$7,'BASE DE DATOS'!$B$2:$AB$685,2,0) -> MONTIEL ROMAN FELIPE
H6: FECHA : | I6: =TODAY() -> 45918
A7: USUARIO No. | C7: 265 | M7: COOPERACIONES | P7: OBSERVACIONES
A9: NOMBRE: | B9: =VLOOKUP($C$7,'BASE DE DATOS'!$B$2:$AB$702,2,0) -> MONTIEL ROMAN FELIPE | H9: =VLOOKUP($C$7,'BASE DE DATOS'!$B$2:$AB$6821,12,0) -> 15 SUR ENTRE 19 Y 21 PTE. | M9: =VLOOKUP($C$7,'BASE DE DATOS'!$B$2:$AB$702,3,0) -> 300 | N9: =VLOOKUP($C$7,'BASE DE DATOS'!$B$2:$AB$702,4,0) -> 150 | P9: =VLOOKUP($C$7,'BASE DE DATOS'!$B$2:$AB$702,11,0) -> 0
A11: TOMAS: | B11: =VLOOKUP($C$7,'BASE DE DATOS'!$B$2:$AB$702,5,0) -> 1 | C11: =IF(B11=0,"HIDRANTE","USUARIO") -> USUARIO | M11: TOMAS: | N11: =VLOOKUP($C$7,'BASE DE DATOS'!$B$2:$AB$702,5,0) -> 1 | O11: =IF(N11=0,"HIDRANTE","USUARIO") -> USUARIO
A12: CONCEPTO | C12: CUOTA X TOMA | D12: 60 | E12: FORMA DE PAGO | F12: VACAS | G12: INQUILINOS | H12: INASISTENCIA | I12: COOPERACIONES | J12: TOMA NUEVA | K12: TOTAL A PAGAR AL 31 DE MARZO 2025 | L12: PAGO | M12: ADEUDO | N12: =VLOOKUP($C$7,'BASE DE DATOS'!$B$2:$AB$702,13,0) -> 2026
C13: CUOTA CON RECARGOS | D13: 100 | E13: =IF(E14>=12,"Anual","Mensual") -> Anual | L13: DESPUES DE LA FECHA | M13: ENERO | N13: =VLOOKUP($C$7,'BASE DE DATOS'!$B$2:$AB$702,14,0) -> 0 | P13: INQUILINO
E14: 12 | F14: =VLOOKUP($C$7,'BASE DE DATOS'!$B$2:$M$702,10,0) -> 0 | G14: =VLOOKUP($C$7,'BASE DE DATOS'!$B$2:$M$702,9,0) -> 0 | M14: FEBRERO | N14: =VLOOKUP($C$7,'BASE DE DATOS'!$B$2:$AB$702,15,0) -> 0 | P14: =VLOOKUP($C$7,'BASE DE DATOS'!$B$2:$AB$702,9,0) -> 0
A15: PAGO POR BOMBEO Y DISTRIBUCION | E15: =IF($B$11=0,$D$12*$E$14,IF($B$11>=1,$D$12*$E$14*$B$11,0)) -> 720 | F15: =((F14*13)*E14) -> 0 | G15: =($G$14*$E$14)*70 -> 0 | H15: =H14*200 -> 0 | K15: =SUM(E15:J15) -> 720 | L15: =E16 -> 1200 | M15: MARZO | N15: =VLOOKUP($C$7,'BASE DE DATOS'!$B$2:$AB$702,16,0) -> 0
A16: DE AGUA POTABLE | E16: =IF($B$11=0,$D$13*$E$14,IF($B$11>=1,$D$13*$E$14*$B$11,0)) -> 1200 | G16: =($G$14*$E$14)*100 -> 0 | I16: =IF($M$9=0,300,0) -> 0 | K16: =SUM(I16:J16) -> 0 | L16: =F15+G16+H15+I16+J16 -> 0 | M16: ABRI | N16: =VLOOKUP($C$7,'BASE DE DATOS'!$B$2:$AB$702,17,0) -> 0
A17: De: | B17: ENERO A DICIEMBRE DE 2025 | I17: =IF($N$9=0,150,0) -> 0 | K17: =SUM(F17:J17) -> 0 | L17: =SUM(I17:J17) -> 0 | M17: MAYO | N17: =VLOOKUP($C$7,'BASE DE DATOS'!$B$2:$AB$702,18,0) -> 0
M18: JUNIO | N18: =VLOOKUP($C$7,'BASE DE DATOS'!$B$2:$AB$702,19,0) -> 0
I19: TOTAL A PAGAR | K19: =SUM(K15:K18) -> 720 | L19: =SUM(L15:L18) -> 1200 | M19: JULIO | N19: =VLOOKUP($C$7,'BASE DE DATOS'!$B$2:$AB$702,20,0) -> 0
M20: AGOTO | N20: =VLOOKUP($C$7,'BASE DE DATOS'!$B$2:$AB$702,21,0) -> 0
M21: SEPTIEMBRE | N21: =VLOOKUP($C$7,'BASE DE DATOS'!$B$2:$AB$702,22,0) -> 0
M22: OCTUBRE | N22: =VLOOKUP($C$7,'BASE DE DATOS'!$B$2:$AB$702,23,0) -> 0
M23: NOVIEMBRE | N23: =VLOOKUP($C$7,'BASE DE DATOS'!$B$2:$AB$702,24,0) -> 0
M24: DICIEMBRE | N24: =VLOOKUP($C$7,'BASE DE DATOS'!$B$2:$AB$702,25,0) -> 0
C25: CARLOS LOPEZ SANTOS | I25: SELLO
A26: NOTA: 1.- ES NECESARIO CONSERVAR ESTE COMPROBANTE, DEBERA PRESENTARLO EN SU PROXIMO PAGO PARA CUALQUIER ACLARACIÓN.
A27: 2.- EL PAGO DE ESTE RECIBO NO TE LIBERA DE DEUDAS ANTERIORES. | L27: USUARIO
K30: FOLIO: | L30: =L2 -> 25265
E32: COMITÉ DE AGUA POTABLE Y ALCANTARILLADO
E33: DEL BARRIO DE SAN ANTONIO TECAMACHALCO, PUE.
H35: FECHA: | I35: =TODAY() -> 45918
A36: USUARIO No. | C36: =C7 -> 265
A38: NOMBRE: | B38: =VLOOKUP($C$7,'BASE DE DATOS'!$B$2:$C$702,2,0) -> MONTIEL ROMAN FELIPE | H38: =VLOOKUP(C36,'BASE DE DATOS'!$B$2:$M$701,12,0) -> 15 SUR ENTRE 19 Y 21 PTE.
A40: TOMAS: | B40: =B11 -> 1 | C40: =C11 -> USUARIO
A41: =A12 -> CONCEPTO | C41: =C12 -> CUOTA X TOMA | D41: =D12 -> 60 | E41: =E12 -> FORMA DE PAGO | F41: =F12 -> VACAS | G41: =G12 -> INQUILINOS | H41: =H12 -> INASISTENCIA | I41: =I12 -> COOPERACIONES | J41: =J12 -> TOMA NUEVA | K41: TOTAL A PAGAR AL 31 DE MARZO 2025 | L41: PAGO
C42: =C13 -> CUOTA CON RECARGOS | E42: =E13 -> Anual | L42: DESPUES DE LA FECHA
D43: 100 | E43: =E14 -> 12 | F43: =F14 -> 0 | G43: =G14 -> 0 | H43: =H14 -> 0
A44: =A15 -> PAGO POR BOMBEO Y DISTRIBUCION | E44: =E15 -> 720 | F44: =F15 -> 0 | G44: =G15 -> 0 | H44: =H15 -> 0 | J44: =J15 -> 0 | K44: =K15 -> 720 | L44: =L15 -> 1200
A45: =A16 -> DE AGUA POTABLE | E45: =E16 -> 1200 | G45: =G16 -> 0 | I45: =I16 -> 0 | K45: =K16 -> 0 | L45: =L16 -> 0
A46: =A17 -> De: | B46: =B17 -> ENERO A DICIEMBRE DE 2025 | I46: =I17 -> 0 | K46: =K17 -> 0 | L46: =L17 -> 0
I48: =I19 -> TOTAL A PAGAR | K48: =K19 -> 720 | L48: =SUM(L44:L47) -> 1200
C54: =C25 -> CARLOS LOPEZ SANTOS | I54: =I25 -> SELLO
A55: =A26 -> NOTA: 1.- ES NECESARIO CONSERVAR ESTE COMPROBANTE, DEBERA PRESENTARLO EN SU PROXIMO PAGO PARA CUALQUIER ACLARACIÓN.
...

Sheet RECIBO PARA LLENAR
E1: COMITÉ DE AGUA POTABLE Y ALCANTARILLADO
E2: DEL BARRIO DE SAN ANTONIO TECAMACHALCO, PUE.
L3: NOTA: FOLIO SE FORMA CON NUMERO DE USUARIO Y AÑO ACTUAL
H5: FECHA: | I5: =TODAY() -> 45918 | L5: =VLOOKUP($C$7,'BASE DE DATOS'!$B$2:$AB$685,2,0) -> FUENTES GONZALEZ GENOVEVA
A7: USUARIO No. | C7: 133 | J7: No. | K7: =CONCATENATE(C7,24) -> 13324 | L7: COOPERACIONES | O7: OBSERVACIONES
A9: NOMBRE: | C9: =VLOOKUP($C$7,'BASE DE DATOS'!$B$2:$AB$702,2,0) -> FUENTES GONZALEZ GENOVEVA | H9: =VLOOKUP($C$7,'BASE DE DATOS'!$B$2:$AB$686,12,0) -> 15 PTE. 1906 | L9: =VLOOKUP($C$7,'BASE DE DATOS'!$B$2:$AB$702,3,0) -> 300 | M9: =VLOOKUP($C$7,'BASE DE DATOS'!$B$2:$AB$702,4,0) -> 150 | O9: =VLOOKUP($C$7,'BASE DE DATOS'!$B$2:$AB$702,11,0) -> 3 EJOTEROS MAYO, junio JULIO AGOSTO 2025
A11: TOMAS: | B11: =VLOOKUP($C$7,'BASE DE DATOS'!$B$2:$AB$702,5,0) -> 1 | C11: =IF(B11=0,"HIDRANTE","USUARIO") -> USUARIO | L11: TOMAS: | M11: =VLOOKUP($C$7,'BASE DE DATOS'!$B$2:$AB$702,5,0) -> 1 | N11: =IF(M11=0,"HIDRANTE","USUARIO") -> USUARIO
A12: CONCEPTO | D12: CUOTA X TOMA | E12: FORMA DE PAGO | F12: VACAS | G12: INQUILINOS | H12: INASISTENCIA | I12: COOPERACIONES | J12: TOMA NUEVA | K12: TOTAL A PAGAR | L12: ADEUDO | M12: =VLOOKUP($C$7,'BASE DE DATOS'!$B$2:$AB$702,13,0) -> 2026
E13: =IF(E14>=12,"Anual","Mensual") -> Mensual | L13: ENERO | M13: =VLOOKUP($C$7,'BASE DE DATOS'!$B$2:$AB$702,14,0) -> PAGA UN INQUILINO ENERO A MAYO 2025 | O13: INQUILINO
D14: 70 | E14: 1 | G14: 3 | L14: FEBRERO | M14: =VLOOKUP($C$7,'BASE DE DATOS'!$B$2:$AB$702,15,0) -> 0 | O14: =VLOOKUP($C$7,'BASE DE DATOS'!$B$2:$AB$702,9,0) -> 1
A15: PAGO POR BOMBEO Y DISTRIBUCION | F15: =((F14*13)*E14) -> 0 | G15: =(G14*E14)*70 -> 210 | H15: =H14*200 -> 0 | K15: =SUM(E15:J15) -> 210 | L15: MARZO | M15: =VLOOKUP($C$7,'BASE DE DATOS'!$B$2:$AB$702,16,0) -> 0
A16: DE AGUA POTABLE | K16: =SUM(E16:J16) -> 0 | L16: ABRI | M16: =VLOOKUP($C$7,'BASE DE DATOS'!$B$2:$AB$702,17,0) -> 0
A17: De: | B17: AGOSTO DE 2025 | K17: =SUM(E17:J17) -> 0 | L17: MAYO | M17: =VLOOKUP($C$7,'BASE DE DATOS'!$B$2:$AB$702,18,0) -> 0
L18: JUNIO | M18: =VLOOKUP($C$7,'BASE DE DATOS'!$B$2:$AB$702,19,0) -> 0
J19: TOTAL | K19: =SUM(K15:K18) -> 210 | L19: JULIO | M19: =VLOOKUP($C$7,'BASE DE DATOS'!$B$2:$AB$702,20,0) -> 0
L20: AGOTO | M20: =VLOOKUP($C$7,'BASE DE DATOS'!$B$2:$AB$702,21,0) -> 0
L21: SEPTIEMBRE | M21: =VLOOKUP($C$7,'BASE DE DATOS'!$B$2:$AB$702,22,0) -> 0
L22: OCTUBRE | M22: =VLOOKUP($C$7,'BASE DE DATOS'!$B$2:$AB$702,23,0) -> 0
L23: NOVIEMBRE | M23: =VLOOKUP($C$7,'BASE DE DATOS'!$B$2:$AB$702,24,0) -> 0
L24: DICIEMBRE | M24: =VLOOKUP($C$7,'BASE DE DATOS'!$B$2:$AB$702,25,0) -> 0
C25: CARLOS LOPEZ SANTOS | I25: SELLO
A27: Nota: Es necesario conservar este comprobante, debera presentarlo en su proximo pago para cualquier aclaración. | K27: USUARIO
E30: COMITÉ DE AGUA POTABLE Y ALCANTARILLADO
E31: DEL BARRIO DE SAN ANTONIO TECAMACHALCO, PUE.
H34: FECHA: | I34: =TODAY() -> 45918
A36: USUARIO No. | C36: =C7 -> 133 | J36: No. | K36: =K7 -> 13324
A38: NOMBRE: | C38: =VLOOKUP($C$7,'BASE DE DATOS'!$B$2:$C$702,2,0) -> FUENTES GONZALEZ GENOVEVA | H38: =VLOOKUP(C36,'BASE DE DATOS'!$B$2:$M$685,12,0) -> 15 PTE. 1906
A40: TOMAS: | B40: =B11 -> 1 | C40: =C11 -> USUARIO
A41: =A12 -> CONCEPTO | D41: =D12 -> CUOTA X TOMA | E41: =E12 -> FORMA DE PAGO | F41: =F12 -> VACAS | G41: =G12 -> INQUILINOS | H41: =H12 -> INASISTENCIA | I41: =I12 -> COOPERACIONES | J41: =J12 -> TOMA NUEVA | K41: =K12 -> TOTAL A PAGAR
E42: =E13 -> Mensual
D43: =D14 -> 70 | E43: =E14 -> 1 | F43: =F14 -> 0 | G43: =G14 -> 3 | H43: =H14 -> 0
A44: =A15 -> PAGO POR BOMBEO Y DISTRIBUCION | E44: =E15 -> 0 | F44: =F15 -> 0 | G44: =G15 -> 210 | H44: =H15 -> 0 | J44: =J15 -> 0 | K44: =K15 -> 210
A45: =A16 -> DE AGUA POTABLE | I45: =I16 -> 0 | J45: =J16 -> 0 | K45: =K16 -> 0
A46: =A17 -> De: | B46: =B17 -> AGOSTO DE 2025 | I46: =I17 -> 0 | K46: =K17 -> 0
J48: =J19 -> TOTAL | K48: =K19 -> 210
C54: =C25 -> CARLOS LOPEZ SANTOS | I54: =I25 -> SELLO
A56: =A27 -> Nota: Es necesario conservar este comprobante, debera presentarlo en su proximo pago para cualquier aclaración. | K56: COMITÉ

Sheet RECIBO
D3: COMITÉ DE AGUA POTABLE Y DRENAJE
D4: DEL BARRIO DE SAN ANTONIO TECAMACHALCO, PUE.
H6: FECHA: | I6: 15 DE NOVIEMBRE 2023 | O6: 225
O7: 840
J8: No. | K8: 4610 | M8: 2399 | N8: 1 | O8: 840
B10: NOMBRE | F10: DIRECCION
A11: 35 | B11: =VLOOKUP(A11,'BASE DE DATOS'!B2:C702,2,0) -> AVELINO NOTARIO LILIA | E11: =VLOOKUP(A11,'BASE DE DATOS'!B2:M685,12,0) -> 21 PTE. ENTRE 7 Y 9 SUR
A13: CONCEPTO | D13: TOTAL MESES | E13: CUOTA | F13: VACAS | G13: INQUILINOS | H13: INASISTENCIA | I13: DRENAJE Y | J13: TOTAL | M13: 2299
I14: EXTRACCION | M14: 1 | N14: 16
A15: PAGO DE AGUA POTABLE DE JUNIO DEL 2023 A JUNIO DEL 2024. | D15: 13 | E15: 60 | F15: 0 | G15: 0 | H15: - | I15: 0 | J15: 780 | N15: 14
N20: =27*70 -> 1890 | O20: =N20*3 -> 5670
L21: =2599+1 -> 2600
M22: =70*24 -> 1680 | N22: 2500 | O22: PAGO DE NUEVA TOMA DE AGUA POTABLE.
M23: 840
B24: TOMAS RAFAEL MOYA LOPEZ | I24: SELLO | M24: 150
M25: =M22-200 -> 1480 | N25: 300 | O25: COOPERACION PARA SECCIONAR RED DE AGUA POTABLE
M26: 2
M27: =J15*M26 -> 1560
O28: PAGO DE AGUA POTABLE DE ENERO A DICIEMBRE DEL 2022.
M30: =1000/70 -> 14.285714
N31: 150 | O31: COOPERACION DE TUBERIA PARA POZO.
M34: 1120 | O34: PAGO DE TOMA NUEVA.
M35: 200
M36: =M34-M35 -> 920
N39: 1000
N40: 14
N44: 2240
N45: 832

Sheet Hoja3
A1: COMENTARIO | B1: No. USUARIO | C1: NOMBRE | F1: TOMA | G1: CONAGUA | H1: DRENAJE | I1: HIDRANTE | J1: INQUILINO | K1: VACAS | M1: DIRECCION | N1: AÑO | O1: ENERO | P1: FEBRERO | Q1: MARZO | R1: ABRIL | S1: MAYO | T1: JUNIO | U1: JULIO | V1: AGOSTO | W1: SEPTIEMBRE | X1: OCTUBRE | Y1: NOVIEMBRE | Z1: DICIEMBRE
B2: 1 | C2: ABUNDIO CRESCENCIO LORENZO | F2: 1 | G2: 320 | M2: 15 PONIENTE ESQ, 7 SUR | N2: 2022 | O2: PAGADO | P2: PAGADO | Q2: PAGADO | R2: PAGADO | S2: PAGADO
B3: 2 | C3: ABUNDIO JIMENEZ LEOBARDO | D3: 300 | E3: 150 | F3: 1 | G3: 320 | M3: 7 SUR ENTRE 11 Y 13 PONIENTE | N3: 2023
B4: 3 | C4: ABUNDIO JIMENEZ ROMARICO | F4: 1 | G4: 320 | M4: 7 SUR ENTRE 11 Y 13 PTE | N4: 2020
B5: 4 | C5: ABUNDIO JUAREZ GABRIELA | D5: 300 | E5: 150 | F5: 1 | G5: 320 | J5: 1 PAGADO HASTA SEP2016 | M5: 7 SUR ENTRE 15 Y 17 PTE. | N5: 2022
B6: 5 | C6: ABUNDIO JUAREZ JOSE LUIS | F6: 1 | G6: 320 | M6: 15 PTE. NO. 2006 | N6: 2022 | O6: PAGADO
A7: CANCELADA | B7: 6 | C7: ABUNDIO JUAREZ ROSA MARIA | F7: 1 | G7: CORTADA | M7: 7 SUR ENTRE 15 Y 17 PONIENTE | N7: 2014 | O7: CORTADA
B8: 7 | C8: ABUNDIO JUAREZ VICTOR GUILLERMO | D8: 300 | F8: 1 | G8: 320 | M8: 7 SUR ENTRE 11 Y 13 PTE. | N8: 2023
B9: 8 | C9: ABUNDIO LOPEZ JESUS MAURO | D9: 600 | E9: 300 | F9: 2 | G9: 320 | M9: 7 SUR ENTRE 11 Y 13 PONIENTE | N9: 2023
A10: CAMBIO DE DOMICILIO | B10: 9 | C10: ABUNDIO RODRIGUEZ LUIS MANUEL | F10: 1 | M10: 15 PTE. NO. 2006 ENT. 7 Y 9 SUR | N10: 2013 | S10: PAGADO | T10: PAGADO | U10: PAGADO | V10: PAGADO
B11: 10 | C11: ADAN GONZALEZ LIDIA | D11: 300 | F11: 1 | G11: 320 | H11: NO | J11: 1INQ.MAYO AGOST 2019 | M11: 9 SUR ENTRE 21 PTE. Y CANAL | N11: 2022
B12: 11 | C12: AGUILAR GUERRERO JESUS | F12: 1 | G12: 320 | H12: NO | M12: 9 SUR ENTRE 21 PTE. Y CANAL | N12: 2020
B13: 12 | C13: ALCANTARA ANGEL AMELIA | D13: 600 | E13: 150 | F13: 2 | G13: 320 | M13: 13 PONIENE 701 ENTRRE 7 Y 9 SUR | N13: 2022 | O13: PAGADO 2 | P13: PAGADO 2 | Q13: PAGADO 2 | R13: PAGADO 2 | S13: PAGADO 2 | T13: PAGADO 2
B14: 13 | C14: ALEJO CASTILLO MERCED | F14: 1 | G14: 320 | M14: 17 PONIENTE ENTRE 17 Y 17 SUR | N14: 2023
A15: CANCELADA | B15: 14 | C15: ALONSO MONTIEL ARIADNA | F15: 1 | M15: 17 SUR ENTRE 15 Y 17 PTE. | N15: 2015
B16: 15 | C16: ALONSO MONTIEL JORGE | F16: 1 | M16: 17 SUR ENTRE 15 Y 17 PTE. | N16: 2019 | O16: PAGADO | P16: PAGADO | Q16: PAGADO | R16: PAGADO | S16: PAGADO
B17: 16 | C17: ANDRADE JIMENEZ JUAN MARIO | F17: 1 | G17: 320 | M17: 11 SUR ENTRE 15 Y 17 PTE. | N17: 2022 | O17: PAGADO | P17: PAGADO | Q17: PAGADO
B18: 17 | C18: ANDRADE LOPEZ LUIS | D18: 300 | E18: 150 | F18: 1 | G18: 320 | M18: 13 SUR ENTRE 21 | N18: 2023
B19: 18 | C19: ANDRADE MENDEZ JUAN | F19: 1 | G19: 320 | M19: 7 PTE. NO. 1503 | N19: 2022 | O19: PAGADO | P19: PAGADO | Q19: PAGADO | R19: PAGADO
B20: 19 | C20: ANDRADE VAZQUEZ FERNANDO | D20: 600 | E20: 300 | F20: 2 | G20: 640 | H20: NO | K20: PAGA 1INQ.3 MESES | M20: 21 PTE. ENTRE 7 Y 9 SUR | N20: 2022 | O20: PAGADO 2 | P20: PAGADO 2 | Q20: PAGADO 2
B21: 20 | C21: APOLINAR VELAZQUEZ JESUS ANTONIO | F21: 1 | G21: 320 | M21: 15 PONIENTEE 710 7 Y 9 SUR | N21: 2020
B22: 21 | C22: ARENAS GONZALEZ JAQUELINE | D22: 300 | E22: 150 | F22: 1 | G22: 320 | H22: NO | M22: 19 PTE. ENTRE 11 Y 13 SUR | N22: 2022 | O22: PAGADO | P22: PAGADO | Q22: PAGADO | R22: PAGADO | S22: PAGADO
B23: 22 | C23: ARENAS GONZALEZ RODOLFO | F23: 1 | G23: 320 | H23: NO | M23: 19 PTE. ESQ. 11 SUR | N23: 2020 | O23: PAGADO | P23: PAGADO | Q23: PAGADO | R23: PAGADO | S23: PAGADO | T23: PAGADO | U23: PAGADO
B24: 23 | C24: GONZALEZ ZUÑIGA MARIA ENRIQUETA | D24: 300 | E24: 150 | F24: 1 | G24: 320 | M24: 11 SUR ENTRE 13 Y 15 PTE. | N24: 2023 | O24: PENDIENTE ASSTENCIAS
B25: 24 | C25: AVELINO MONTIEL FERNANDO | D25: 300 | F25: 1 | G25: 320 | H25: NO | M25: 9 SUR ENTRE 19 Y 21 PTE. | N25: 2023
B26: 25 | C26: AVELINO ALEJO DANIEL | D26: 300 | F26: 1 | G26: 320 | M26: 13 PONIENTE Y 15 SUR | N26: 2023 | O26: PEN DIENE ASISTENCIAS
B27: 26 | C27: AVELINO ALEJO MIGUEL | F27: 1 | G27: 320 | M27: 15 SUR 1107 | N27: 2023
B28: 27 | C28: AVELINO ANDRADE RUTH | D28: 300 | E28: 150 | F28: 1 | G28: 320 | M28: 7 SUR ESQ, 17 PTE. | N28: 2023
B29: 28 | C29: AVELINO HERNANDEZ GABRIEL | F29: 1 | G29: 320 | H29: NO | M29: 21 PTE. ENTRE 7 Y 9 SUR5 | N29: 2023
B30: 29 | C30: AVELINO MONTIEL EMILIA | D30: 300 | E30: 150 | F30: 1 | G30: 320 | H30: NO | M30: 13 SUR ENTRE CANAL Y BARRANCA | N30: 2023
B31: 30 | C31: AVELINO MONTIEL GUADALUPE | E31: 150 | F31: 1 | G31: 320 | H31: NO | M31: 9 SUR ENTRE 19 Y 21 PTE | N31: 2020 | O31: PAGADO | P31: PAGADO | Q31: PAGADO | R31: PAGADO | S31: PAGADO | T31: PAGADO | U31: PAGADO | V31: PAGADO | W31: PAGADO
B32: 31 | C32: AVELINO MONTIEL LUCIA | D32: 600 | E32: 150 | F32: 2 | G32: 640 | H32: y si la paga | J32: 1 INQ HASTA SEP 2017 | K32: 43252 | M32: 13 SUR 1105 Y 9 SUR | N32: 2023 | X32: PAGADO 1 | Y32: PAGADO 1 | Z32: PAGADO 1
B33: 32 | C33: AVELINO MONTIEL MARCELA | D33: 300 | F33: 1 | G33: 320 | I33: PAGO 4INQ. MAYO2019 | M33: 13 SUR NO. 1102 ENTRE 11 Y 13 PON | N33: 2022 | O33: PAGADO | P33: PAGADO | Q33: PAGADO | R33: PAGADO | S33: PAGADO | T33: PAGADO
B34: 33 | C34: AVELINO NOTARIO EFRAIN | D34: 300 | F34: 1 | G34: 320 | H34: NO | M34: TRE 7 Y 9 SUR | N34: 2022 | O34: PAGADO | P34: PAGADO | Q34: PAGADO
B35: 34 | C35: AVELINO NOTARIO GILBERTO | D35: 300 | F35: 1 | G35: 320 | H35: NO | M35: 21 PTE. ENTRE 7 Y 9 SUR5 | N35: 2022
B36: 35 | C36: AVELINO NOTARIO LILIA | F36: 1 | G36: 320 | H36: NO | M36: 21 PTE. ENTRE 7 Y 9 SUR | N36: 2021 | O36: PAGADO | P36: PAGADO | Q36: PAGADO | R36: PAGADO | S36: PAGADO | T36: PAGADO | U36: PAGADO | V36: PAGADO
B37: 36 | C37: AVELINO NOTARIO MARIELA | D37: 300 | F37: 1 | G37: 320 | M37: 21 PTE. ENTRE 7 Y 9 SUR5 | N37: 2022
B38: 37 | C38: AVELINO NOTARIO MONICA | F38: 1 | G38: 320 | H38: NO | M38: 21 PTE. ENTRE 7 Y 9 SUR | N38: 2019 | O38: PAGADO | P38: PAGADO | Q38: PAGADO | R38: PAGADO | S38: PAGADO | T38: PAGADO | U38: PAGADO | V38: PAGADA
A39: CANCELADA | B39: 38 | C39: AVELINO OJEDA ABRAHAM | F39: 1 | M39: 9 SUR ENTRE 21 PTE | N39: 2017 | O39: CANCELADA
B40: 39 | C40: AVELINO ROBLES CANDELARIA | D40: 600 | E40: 300 | F40: 2 | G40: 320 | H40: NO | M40: 11 SUR ENTRE 21 PTE. Y CANAL | N40: 2023
...

Sheet Hoja2
B1: TOMAS ENTREGADAS 2020-2021
B2: USUARIO | C2: NOMBRE | D2: DRENAJE | E2: AGUA | F2: AGUA-DRENAJE
B3: 25 | C3: AVELINO ALEJO DANIEL | D3: X
B4: 34 | C4: AVELINO NOTARIO GILBERTO | E4: X
B5: 51 | C5: AVELINO SANTOS GRICELDA | F5: X
B6: 60 | C6: BENITEZ RAMOS MARIA CONCEPCION | D6: X
B7: 178 | C7: PELAEZ JUAREZ MA. DE LOURDES | D7: X
B8: 197 | C8: LEON RODRIGUEZ GABRIELA | F8: X
B9: 277 | C9: MORALES DE LOS SANTOS MARTHA | F9: X
B10: 369 | C10: RODRIGUEZ MALDONADO GABINO | F10: X
B11: 373 | C11: RODRIGUEZ MALDONADO VIRGINIA | F11: X
B12: 437 | C12: ROSAS LUNA MANUEL | D12: X
B13: 439 | C13: FERNANDEZ SANTOS MARIBEL | F13: X
B14: 471 | C14: SANCHEZ VARGAS DIANA LAURA | F14: X
B15: 497 | C15: SANTOS MARTINEZ GUILIANI CLAUDIA | F15: X
B16: 514 | C16: SANTOS ZAMORA YOLANDA | F16: X
B17: 556 | C17: VILLAFAN LEON ARACELI | F17: X
B18: 557 | C18: VILLAFAN LEON CECILIA | E18: X
B19: 560 | C19: VILLAFAN LEON OSCAR | F19: X
B20: 566 | C20: ZAYAGOS GUEVARA MIGUEL | D20: X
B21: 585 | C21: ROSAS MOLINA DELFINO | F21: X
B22: 596 | C22: RODRIGUEZ VELEZ ALBERTO | E22: X
B23: 600 | C23: LEON RODRIGUEZ LORENA | F23: X
B24: 615 | C24: MENDEZ CLEMENTE VALENTIN PASCUAL | E24: X
B25: 619 | C25: GUZMAN TRINIDAD TOMASA | F25: X
B26: 620 | C26: LEON LOPEZ PEDRO | F26: X
B27: 626 | C27: SANDOVAL DE LA CRUZ ERICA | F27: X
B28: 627 | C28: MACHORRO MONTIEL PASCUAL | F28: X
B29: 628 | C29: MACHORRO MONTIEL RUBEN | F29: X
B30: 629 | C30: MOLINA CORTES ELVIRA | F30: X
B31: 630 | C31: MOLINA CORTES SEBASTIANA | F31: X
B32: 631 | C32: NOTARIO ANDRADE MOISES | F32: X
B33: 632 | C33: VALENCIA VALENCIA MARGARITA | F33: X
B34: 634 | C34: ALEJO FLORES BRAYAN | F34: X
B35: 635 | C35: GARCIA SANCHEZ SILVIA | F35: X
B36: 636 | C36: RODRIGUEZ MORALES MARGARITA | F36: X
... B42: 644 | C42: CANDIA ROSAS GABRIELA | F42: X

Sheet Hoja11

Sheet Hoja1
D3: COMITÉ DE AGUA POTABLE Y DRENAJE
D4: DEL BARRIO DE SAN ANTONIO TECAMACHALCO, PUE.
H6: FECHA:
J8: No.
A10: USUARIO | B10: NOMBRE | F10: DIRECCION
A13: DESCRIPCION | D13: TOTAL | E13: CUOTA | F13: VACAS | G13: INQUILINOS | H13: INASISTENCIA | I13: DRENAJE Y | J13: TOTAL
I14: EXTRACCION
E15: 45 | I15: 0
B24: TOMAS RAFAEL MOYA LOPEZ | I24: SELLO

Sheet PAGOS 2011 A 2015
A1: USUARIOS 2011,2012,2013
A2: No. USUARIO | B2: NOMBRE | C2: TOMA | D2: DIRECCION | E2: AÑO | F2: ENERO | G2: FEBRERO | H2: MARZO | I2: ABRIL | J2: MAYO | K2: JUNIO | L2: JULIO | M2: AGOSTO | N2: SEP | O2: OCT | P2: NOV | Q2: DIC
A3: 9 | B3: ABUNDIO RODRIGUEZ LUIS MANUEL | C3: 1 | D3: 15 PTE. NO. 2006 ENT. 7 Y 9 SUR | E3: 2013 | F3: (cambio de domicilio) | J3: PAGADO | K3: PAGADO | L3: PAGADO | M3: PAGADO
A4: 304 | B4: ORTIZ REYES ALEJANDRO | D4: 15 SUR ENTRE 13 Y 15 PTE. | E4: 2013 | F4: (cambio de domicilio)
A5: 397 | B5: RODRIGUEZ TELLEZ JUAN | D5: 15 SUR ENTRE 13 Y 15 PTE. | E5: 2011 | F5: PAGADO | G5: PAGADO | H5: PAGADO | I5: PAGADO | J5: PAGADO | K5: (cambio de domicilio)
A6: 536 | B6: TRUJILLO BERISTAIN FELIPE | C6: 1 | D6: CARRETERA A XOCHITLAN | E6: 2013 | F6: (no le lleg agua)
A7: 553 | B7: VERA MORENO MARIA | D7: 15 ENTRE 13 Y 21 PTE. | E7: 2011 | F7: NUERA DE DOÑA PAULINA
A8: 579 | B8: RIOS REYES CYNAI | D8: 15 SUR 1304 | E8: 2012
A12: USUARIOS 2014, 2015
A13: No. USUARIO | B13: NOMBRE | C13: TOMA | D13: DIRECCION | E13: AÑO | F13: ENERO | G13: FEBRERO | H13: MARZO | I13: ABRIL | J13: MAYO | K13: JUNIO | L13: JULIO | M13: AGOSTO | N13: SEP | O13: OCT | P13: NOV | Q13: DIC
A14: 203 | B14: LOPEZ ANDRADE INES | C14: 1 | D14: 7 SUR ANTRE 13 Y 11 PTE. | E14: 2014
A15: 206 | B15: LOPEZ BAURET MIGUEL ANGEL | C15: 1 | D15: 15 PTE. ENTRE 7 SUR | E15: 2015 | F15: PAGADO | G15: PAGADO | H15: PAGADO | I15: PAGADO | J15: PAGADO | K15: PAGADO
A16: 225 | B16: LOPEZ SANCHEZ MARIA AMELIA | D16: 15 PTE ENTRE 7 Y 0 SUR | E16: 2014 | F16: PAGADO | G16: PAGADO | H16: PAGADO | I16: PAGADO | J16: PAGADO | K16: PAGADO
A17: 227 | B17: LOPEZ SANCHEZ MARIA DE LOURDES | E17: 2014 | F17: PAGADO | G17: PAGADO | H17: PAGADO | I17: PAGADO | J17: PAGADO | K17: PAGADO | L17: PAGADO | M17: PAGADO
A18: 244 | B18: MALDONADO PELAEZ ALEJANDRO | D18: 17 PTE. ENTRE 15 Y 17 SUR | E18: 2014 | F18: PAGADO
A19: 263 | B19: MONTIEL OREA MOISES MAXIMILIANO | C19: 1 | D19: 13 SUR ENTRE 19 Y 21 PTE. | E19: 2015 | F19: PAGADO | G19: PAGADO | H19: PAGADO | I19: PAGADO | J19: PAGADO | K19: PAGADO
A20: 273 | B20: MONTIEL VILLEGAS MARINA | D20: 13 SUR ENTRE 19 Y 21 PTE. | E20: 2014 | F20: PAGADO | G20: PAGADO | H20: PAGADO | I20: PAGADO | J20: PAGADO
A21: 345 | B21: RODRIGUEZ CRISTOBAL MARIA FELIX | C21: 1 | D21: 9 SUR ENTRE 15 Y 17 PTE. | E21: 2014 | F21: PAGADO | G21: PAGADO | H21: PAGADO
A22: 391 | B22: RODRIGUEZ SANTOS ANGELA | D22: 17 PTE. ENTRE 19 SUR Y CANAL | E22: 2014 | F22: (vive en casa de su hermana)
A23: 403 | B23: RODRIGUEZ VELEZ ROCIO | D23: 15 PTE. ESQ. 19 SUR | E23: 2015 | F23: PAGADO | G23: PAGADO | H23: PAGADO
A24: 434 | B24: ROSAS HERNANDEZ FABIAN | D24: 15 PONIENTEE 19 SUR 1710 | E24: 2014 | F24: PAGADO
A25: 465 | B25: SANCHEZ DAVILA GUADALUPE | C25: 1 | D25: 13 SUR ENTRE 21 PTE. Y CANAL | E25: 2014
A26: 476 | B26: SANTOS DEONATE ANTONIO | C26: 1 | D26: 17 SUR ENTRE 13 Y 15 PTE. | E26: 2014
A27: 478 | B27: SANTOS DEONATE EULALIO | C27: 1 | D27: 17 SUR ENTRE 13 Y 15 PTE. | E27: 2015 | F27: PAGADO | G27: PAGADO | H27: PAGADO | I27: PAGADO | J27: PAGADO | K27: PAGADO | L27: PAGADO | M27: PAGADO | N27: PAGADO | O27: PAGADO | P27: PAGADO
A28: 525 | B28: TELLEZ SANTOS ESPERANZA | C28: 1 | D28: 15 SUR ENTRE 13 Y 15 PTE | E28: 2014 | F28: PAGADO | G28: PAGADO | H28: PAGADO
A29: 533 | B29: TREJO RODRIGUEZ CLAUDIA | C29: 1 | D29: 11 SUR ENTRE 15 Y 17 PTE. | E29: 2015
A30: 537 | B30: TRUJILLO VEGA VALENTIN | C30: 1 | D30: 15 SUR ENTRE 11 Y 13 PTE | E30: 2015 | F30: PAGADO | G30: PAGADO | H30: PAGADO | I30: PAGADO | J30: PAGADO | K30: PAGADO | L30: PAGADO | M30: PAGADO
A31: 554 | B31: VERA ROMERO FRANCISCO | C31: 1 | D31: 17 PTE. ENTRE 11 Y 13 SUR | E31: 2015 | F31: PAGADO | G31: PAGADO | H31: PAGADO | I31: PAGADO | J31: PAGADO | K31: PAGADO | L31: PAGADO | M31: PAGADO | N31: PAGADO | O31: PAGADO | P31: PAGADO
A32: 572 | B32: DEONATE FERNANDEZ MARCELA | C32: 1 | D32: 15 PONIENTEE 1113 | E32: 2014
A33: 592 | B33: CHAVEZ MACHORRO SALVADOR | C33: 1 | D33: 19 PONIENTE NO. 1107 ENTRE LA 13 SUR | E33: 2015 | F33: PAGADO | G33: PAGADO | H33: PAGADO | I33: PAGADO | J33: PAGADO | K33: PAGADO | L33: PAGADO

Sheet CANCELADAS
A1: No. USUARIO | B1: NOMBRE | C1: TOMA | D1: DIRECCION | E1: AÑO
A2: 6 | B2: ABUNDIO JUAREZ ROSA MARIA | C2: 1 | D2: 7 SUR ENTRE 15 Y 17 PONIENTE | E2: cancelada 2014
A3: 14 | B3: ALONSO MONTIEL ARIADNA | C3: 1 | D3: 17 SUR ENTRE 15 Y 17 PTE. | E3: cortada 2015
A4: 38 | B4: AVELINO OJEDA ABRAHAM | C4: 1 | D4: 9 SUR ENTRE 21 PTE | E4: cancelada 2012
A5: 56 | B5: AVELINO SANTOS VILIULFO | C5: 1 | D5: 21 PONIENTE NUM. 709, SAN ANTONIO | E5: cancelada en jul 2017
A6: 62 | B6: BONILLA MUÑOZ HILDA | C6: 1 | D6: 9 SUR ENTRE 21 PTE Y CANAL | E6: cancelada 2010
A7: 167 | B7: JIMENEZ ARISTA VICTOR ADAN | C7: 1 | D7: 9 SUR ENTRE 21 PTE Y CANAL | E7: cancelada 2011
A8: 272 | B8: MONTIEL VILLEGAS KARINA | C8: 1 | D8: 13 SUR ENTRE 19 Y 21 PTE. | E8: cortada (pago de ene-2011 a oct-2013 recibo por $1565.00
A9: 298 | B9: NOTARIO LEON MIGUEL | D9: 9 SUR ENTRE 13 Y 15 PTE. | E9: cancelado (pago todo 2016)
A10: 299 | B10: OJEDA NOTARIO AGUSTIN | C10: 1 | D10: DIAGONAL PREPA | E10: cancelada en sep-2013
A11: 311 | B11: PELAEZ JIMENEZ MARIA DEL CARMEN | C11: 1 | D11: 13 SUR ENTRE 19 Y 21 PTE. | E11: cancelada en 2010
A12: 321 | B12: PELAEZ RIOS JOSEFINA | C12: 1 | D12: 17 SUR ENTRE 17 PTE Y CANAL | E12: cancelada (pago de ene-2011 a jul 2016 )
A13: 330 | B13: PORRAS HUERTA MARIA DE LOS ANGELES | C13: 1 | D13: 21 PTE. ENTRE 9 Y 11 SUR | E13: finado Don Juan (no ah pagado el 2014 se le dio recibo por error
A14: 338 | B14: REYES TELLES AMELIA | D14: 15 SUR ENTRE 13 Y 15 PTE. | E14: cortada (pago hasta jun- 2012)
A15: 350 | B15: RODRIGUEZ GARCIA ALEJANDRO | C15: 1 | E15: no vive aquí
A16: 438 | B16: ROSAS NOTARIO FACUNDO | D16: 15 PTE. ESQ. 13 SUR | E16: (se da de baja 2017)
A17: 551 | B17: VELEZ DAVILA JESUS | D17: DIAGONAL PREPA | E17: cancelada en 2010

Sheet PAGOS 2016, 2017
A1: USUARIOS 2014, 2015
A2: No. USUARIO | B2: NOMBRE | C2: TOMA | D2: DIRECCION | E2: AÑO | F2: ENERO | G2: FEBRERO | H2: MARZO | I2: ABRIL | J2: MAYO | K2: JUNIO | L2: JULIO | M2: AGOSTO | N2: SEP | O2: OCT | P2: NOV | Q2: DIC
A3: 17 | B3: ANDRADE LOPEZ LUIS | C3: 1 | D3: 13 SUR ENTRE 21 | E3: 2017 | F3: PAGADO | G3: PAGADO | H3: PAGADO | I3: PAGADO
A4: 18 | B4: ANDRADE MENDEZ JUAN | C4: 1 | D4: 7 PTE. NO. 1503 | E4: 2017 | F4: PAGADO | G4: PAGADO | H4: PAGADO | I4: PAGADO | J4: PAGADO | K4: PAGADO | L4: PAGADO | M4: PAGADO | N4: PAGADO | O4: PAGADO
A5: 19 | B5: ANDRADE VAZQUEZ FERNANDO | C5: 2 | D5: 21 PTE. ENTRE 7 Y 9 SUR | E5: 2017 | F5: PAGADO 2 | G5: PAGADO 2 | H5: PAGADO2 | I5: PAGADO2 | J5: PAGADO 2 | K5: PAGADO2
A6: 20 | B6: APOLINAR VELAZQUEZ JESUS ANTONIO | C6: 1 | D6: 15 PONIENTEE 710 7 Y 9 SUR | E6: 2017 | F6: PAGADO | G6: PAGADO | H6: PAGADO | I6: PAGADO | J6: PAGADO | K6: PAGADO | L6: PAGADO | M6: PAGADO | N6: PAGADO | O6: PAGADO | P6: PAGADO
A7: 21 | B7: ARENAS GONZALEZ JAQUELINE | C7: 1 | D7: 19 PTE. ENTRE 11 Y 13 SUR | E7: 2017
A8: 22 | B8: ARENAS GONZALEZ RODOLFO | C8: 1 | D8: 19 PTE. ESQ. 11 SUR | E8: 2017 | F8: PAGADO | G8: PAGADO | H8: PAGADO | I8: PAGADO | J8: PAGADO | K8: PAGADO
A9: 23 | B9: GONZALEZ ZUÑIGA MARIA ENRIQUETA | C9: 1 | D9: 11 SUR ENTRE 13 Y 15 PTE. | E9: 2017
A10: 25 | B10: AVELINO ALEJO DANIEL | C10: 1 | D10: 13 PONIENTE Y 15 SUR | E10: 2017
A11: 26 | B11: AVELINO ALEJO MIGUEL | C11: 1 | D11: 15 sur 1107 | E11: 2017
A12: 27 | B12: AVELINO ANDRADE RUTH | C12: 1 | D12: 7 SUR ESQ, 17 PTE. | E12: 2017
A13: 28 | B13: AVELINO HERNANDEZ GABRIEL | C13: 1 | D13: 21 PTE. ENTRE 7 Y 9 SUR5 | E13: 2017 | F13: PAGADO | G13: PAGADO | H13: PAGADO | I13: PAGADO
A14: 29 | B14: AVELINO MONTIEL EMILIA | C14: 1 | D14: 13 SUR ENTRE CANAL Y BARRANCA | E14: 2017 | F14: PAGADO | G14: PAGADO
A15: 30 | B15: AVELINO MONTIEL GUADALUPE | C15: 1 | D15: 9 SUR ENTRE 19 Y 21 PTE | E15: 2017 | F15: PAGADO | G15: PAGADO | H15: PAGADO | I15: PAGADO | J15: PAGADO | K15: PAGADO | L15: PAGADO | M15: PAGADO | N15: PAGADO
A16: 31 | B16: AVELINO MONTIEL LUCIA | C16: 2 | D16: 13 SUR 1105 Y 9 SUR | E16: 2017 | F16: PAGADO 2 | G16: PAGADO 2 | H16: PAGADO 2 | I16: PAGADO 2 | J16: PAGADO 2 | K16: PAGADO 2 | L16: PAGADO 2 | M16: PAGADO 2 | N16: PAGADO 2 | O16: PAGADO 2 | P16: PAGADO 2 | Q16: PAGADO 2
A17: 32 | B17: AVELINO MONTIEL MARCELA | C17: 1 | D17: 13 SUR NO. 1102 ENTRE 11 Y 13 PON | E17: 2017
A18: 33 | B18: AVELINO NOTARIO EFRAIN | C18: 1 | D18: TRE 7 Y 9 SUR | E18: 2017 | F18: PAGADO | G18: PAGADO | H18: PAGADO | I18: PAGADO | J18: PAGADO | K18: PAGADO | L18: PAGADO | M18: PAGADO
A19: 34 | B19: AVELINO NOTARIO GILBERTO | C19: 1 | D19: 21 PTE. ENTRE 7 Y 9 SUR5 | E19: 2017 | F19: PAGADO | G19: PAGADO | H19: PAGADO | I19: PAGADO | J19: PAGADO | K19: PAGADO
A20: 35 | B20: AVELINO NOTARIO LILIA | C20: 1 | D20: 21 PTE. ENTRE 7 Y 9 SUR | E20: 2017
A21: 36 | B21: AVELINO NOTARIO MARIELA | C21: 1 | D21: 21 PTE. ENTRE 7 Y 9 SUR5 | E21: 2017
A22: 39 | B22: AVELINO ROBLES CANDELARIA | C22: 1 | D22: 11 SUR ENTRE 21 PTE. Y CANAL | E22: 2017
A23: 40 | B23: AVELINO ROBLES JUANA | C23: 2 | D23: 1 T /21 PONIENTE 1T/ 17 SUR 1502 | E23: 2017
A24: 41 | B24: AVELINO ROBLES MARGARITA | C24: 2 | D24: 11 SUR ENTRE 21 PTE. Y CANAL | E24: 2017
A25: 42 | B25: AVELINO ROMERO AGUSTINA | C25: 1 | D25: 19 PONIENTE ESQ. 9 SUR | E25: 2017
A26: 43 | B26: AVELINO ROMERO JOSE MIGUEL | C26: 3 | D26: 13 SUR ESQUINA 15 PTE | E26: 2017
A27: 44 | B27: AVELINO ROMERO MANUEL | C27: 2 | D27: 11 SUR ENTRE 19 Y 21 PTE. | E27: 2017
A28: 45 | B28: AVELINO ROMERO MARCELINO | C28: 1 | E28: 2017
A29: 46 | B29: AVELINO ROMERO MAURA | C29: 1 | D29: 19 PTE. ESQ. 9 SUR | E29: 2017
A30: 47 | B30: AVELINO ROMERO MAXIMINO | C30: 1 | D30: 9 SUR ENTRE 19 Y 21 PTE. | E30: 2017
A31: 48 | B31: AVELINO SANTOS ALFONSO | C31: 1 | D31: 9 SUR ENTRE 19 Y 21 PTE. | E31: 2017
A32: 49 | B32: AVELINO SANTOS FRANCISCO | C32: 1 | D32: 11 SUR ENTRE LA 21 Y LATERAL VALSEQUILLO | E32: 2017 | F32: PAGADO
A33: 50 | B33: AVELINO SANTOS GAUDENCIO | C33: 1 | D33: 21 PTE- ESQ. 7 SUR | E33: 2017 | F33: PAGADO | G33: PAGADO | H33: PAGADO | I33: PAGADO
A34: 51 | B34: AVELINO SANTOS GRICELDA | D34: 11 SUR ENTRE 21 PTE. Y CANAL | E34: 2017
A35: 52 | B35: AVELINO SANTOS HERMELINDA GUADALUPE | C35: 1 | D35: 11 SUR ENTRE 21 PTE, Y CANAL | E35: 2017 | F35: PAGADO | G35: PAGADO | H35: PAGADO | I35: PAGADO | J35: PAGADO | K35: PAGADO
A36: 53 | B36: AVELINO SANTOS JULIA | C36: 1 | D36: 11 SUR ENTRE 21 PTE. Y CANAL | E36: 2017 | F36: PAGADO | G36: PAGADO | H36: PAGADO | I36: PAGADO | J36: PAGADO | K36: PAGADO | L36: PAGADO | M36: PAGADO | N36: PAGADO | O36: PAGADO | P36: PAGADO | Q36: PAGADO
A37: 54 | B37: SANTOS PELAEZ MARCELO | C37: 2 | D37: CALLE 15 SUR 1306 SAN ANTONIO | E37: 2017 | F37: PAGADO 2 | G37: PAGADO2 | H37: PAGADO2 | I37: PAGADO2 | J37: PAGADO2
A38: 55 | B38: AVELINO SANTOS NATIVIDAD | C38: 1 | D38: 9 SUR ENTRE 21 PTE Y CANAL | E38: 2017 | F38: PAGADO | G38: PAGADO | H38: PAGADO | I38: PAGADO | J38: PAGADO | K38: PAGADO | L38: PAGADO | M38: PAGADO | N38: PAGADO | O38: PAGADO | P38: PAGADO | Q38: PAGADO
A39: 57 | B39: BARCENAS AVELINO EDITH | D39: 7 SUR ESQ. 11 PTE. | E39: 2017
A40: 58 | B40: BECERRA SANCHEZ JESUS | C40: 1 | D40: 17 SUR ENTRE 17 PTE Y CANAL | E40: 2017 | F40: PAGADO | G40: PAGADO | H40: PAGADO | I40: PAGADO | J40: PAGADO | K40: PAGADO | L40: PAGADO | M40: PAGADO | N40: PAGADO | O40: PAGADO | P40: PAGADO | Q40: PAGADO
...

Sheet PAGOS 2018
A1: USUARIOS 2018
A2: No. USUARIO | B2: NOMBRE | C2: TOMA | D2: DIRECCION | E2: AÑO | F2: ENERO | G2: FEBRERO | H2: MARZO | I2: ABRIL | J2: MAYO | K2: JUNIO | L2: JULIO | M2: AGOSTO | N2: SEPT | O2: OCT | P2: NOV | Q2: DIC
A3: 16 | B3: ANDRADE JIMENEZ JUAN MARIO | C3: 1 | D3: 11 SUR ENTRE 15 Y 17 PTE. | E3: 2018 | F3: PAGADO | G3: PAGADO | H3: PAGADO | I3: PAGADO | J3: PAGADO | K3: PAGADO | L3: PAGADO | M3: PAGADO | N3: PAGADO | O3: PAGADO | P3: PAGADO | Q3: PAGADO
A4: 106 | B4: DE LOS ANGELES ISLAS MIGUEL | C4: 1 | D4: 11 SUR ENTRE 15 Y 17 PTE | E4: 2018 | F4: PAGADO | G4: `PAGADO | H4: PAGADO | I4: PAGADO
A5: 146 | B5: GARCIA ORTIZ YOLANDA | C5: 1 | D5: 11 PTE. ESQ. 7 SUR | E5: 2018 | F5: PAGADO | G5: PAGADO | H5: PAGADO | I5: PAGADO | J5: PAGADO
A6: 196 | B6: LEON RODRIGUEZ CESAR | D6: 19 SUR ENTRE 15 Y 17 PONIENTE | E6: 2018 | F6: PAGADO | G6: PAGADO | H6: PAGADO | I6: PAGADO | J6: PAGADO | K6: PAGADO
A7: 198 | B7: LEON RODRIGUEZ RODRIGO | C7: 1 | D7: 19 SUR ENTRE 15 Y 17 PTE. | E7: 2018 | F7: PAGADO | G7: PAGADO | H7: PAGADO | I7: PAGADO | J7: PAGADO
A8: 211 | B8: LOPEZ GARCIA JOSE GUADALUPE | C8: 1 | D8: 21 PINIENTE SN NUMERO | E8: 2018
A9: 213 | B9: LOPEZ GONZALEZ GERARDO | C9: 1 | D9: 13 PTE. ENTRE 13 Y 15 SUR | E9: 2018 | F9: PAGADO | G9: PAGADO | H9: PAGADO | I9: PAGADO | J9: PAGADO | K9: PAGADO
A10: 215 | B10: LOPEZ LOPEZ CELINA | C10: 1 | D10: 15 PTE. ESQ. 7 SUR | E10: 2018 | F10: PAGADO | G10: PAGADO | H10: PAGADO | I10: PAGADO | J10: PAGADO | K10: PAGADO | L10: PAGADO | M10: PAGADO
A11: 226 | B11: LOPEZ SANCHEZ MARIA CANDELARIA | D11: 13 SUR ENTRE 21 PTE Y CANAL | E11: 2018 | F11: PAGADO | G11: PAGADO | H11: PAGADO | I11: PAGADO | J11: PAGADO | K11: PAGADO
A12: 230 | B12: LOPEZ SANCHEZ RUFINO | C12: 1 | D12: 15 PTE. ENTRE 7 Y 9 SUR | E12: 2018 | F12: PAGADO | G12: PAGADO | H12: PAGADO | I12: PAGADO | J12: PAGADO | K12: PAGADO | L12: PAGADO | M12: PAGADO
A13: 236 | B13: LOPEZ SANTOS RICARDO | C13: 1 | D13: 15 PTE. ESQ. 7 SUR | E13: 2018
A14: 246 | B14: ALONSO PELEZ ANALLELY | D14: CAMINO REAL SI NUMERO | E14: 2018 | F14: PAGADO | G14: PAGADO | H14: PAGADO | I14: PAGADO | J14: PAGADO | K14: PAGADO | L14: PAGADO
A15: 248 | B15: MARTINEZ GONZALEZ JOSE LUIS | D15: 17 SUR ENTRE 17 PTE. Y CANAL | E15: 2018 | F15: PAGADO | G15: PAGADO | H15: PAGADO | I15: PAGADO | J15: PAGADO | K15: PAGADO | L15: PAGADO | M15: PAGADO
A16: 251 | B16: MARTINEZ RAMIREZ GREGORIA | C16: 1 | D16: 15 SUR ENTRE 19 Y 21 PTE. | E16: 2018
A17: 255 | B17: MENDEZ SANTOS ELADIO | C17: 1 | D17: 17 SUR ENTRE 17 PTE Y CANAL | E17: 2018 | F17: PAGADO | G17: PAGADO | H17: PAGADO | I17: PAGADO | J17: PAGADO | K17: PAGADO | L17: PAGADO | M17: PAGADO | N17: PAGADO | O17: PAGADO | P17: PAGADO
A18: 265 | B18: MONTIEL ROMAN FELIPE | C18: 1 | D18: 15 SUR ENTRE 19 Y 21 PTE. | E18: 2018 | F18: PAGADO | G18: PAGADO | H18: PAGADO
A19: 270 | B19: MONTIEL ROMAN SUSANA | C19: 1 | D19: 19 PTE. ENTRE 11 Y 13 PTE. | E19: 2018 | F19: PAGADO | G19: PAGADO | H19: PAGADO | I19: PAGADO | J19: PAGADO | K19: PAGADO | L19: PAGADO | M19: PAGADO | N19: PAGADO
A20: 275 | B20: MORALES AGUILERA ANA ELSA | C20: 1 | D20: 15 SUR ENTRE 17 PTE. Y CANAL | E20: 2018 | F20: PAGADO | G20: PAGADO | H20: PAGADO | I20: PAGADO | J20: PAGADO | K20: PAGADO
A21: 280 | B21: MORO ORTIZ INES | C21: 1 | D21: 15 PTE. ENTRE 11 Y 13 SUR | E21: 2018 | F21: PAGADO | G21: PAGADO | H21: PAGADO | I21: PAGADO | J21: PAGADO | K21: PAGADO | L21: PAGADO | M21: PAGADO
A22: 290 | B22: NIÑO ROMERO NOE | C22: 1 | D22: DIAGONAL PREPA | E22: 2018
A23: 292 | B23: NOGALES REYES MARGARITA | C23: 1 | D23: 15 SUR ENTRE 19 Y 21 PTE. | E23: 2018 | F23: PAGADO | G23: PAGADO | H23: PAGADO | I23: PAGADO
A24: 296 | B24: NOTARIO LIMON CONCEPCION | C24: 1 | D24: 17 PTE. Y 13 SUR | E24: 2018 | F24: PAGADO | G24: PAGADO | H24: PAGADO | I24: PAGADO | J24: PAGADO | K24: PAGADO | L24: PAGADO | M24: PAGADO | N24: PAGADO
A25: 297 | B25: PELAEZ VALENTIN ALEJANDRA ISAMAR | D25: 17 SUR 1702 A | E25: 2018
A26: 308 | B26: PELAEZ JIMENEZ ESTEBAN | C26: 1 | D26: 13 PTE ENTRE 17 Y 19 SUR | E26: 2018
